Workbook

Sheet لوحة المعلومات
A1: لوحة معلومات أسطول المركبات - فرع الدمام
A2: تاريخ آخر تحديث: | B2: 46194 | D2: تاريخ اليوم: | E2: =TODAY() -> 46261
A4: إجمالي عدد السائقين | C4: عدد الموصلين | E4: عدد الموزعين | G4: سائقون في إجازة | I4: مركبات أسبير/معطلة
A5: =COUNTA('سجل النقل'!B5:B33)+COUNTA('سجل الخاص'!B5:B31) -> 56 | C5: =COUNTIF('سجل النقل'!E5:E33,"موصل") -> 17 | E5: =COUNTIF('سجل النقل'!E5:E33,"موزع") -> 12 | G5: =COUNTA('السائقون في إجازة'!B4:B5) -> 2 | I5: =COUNTA('الأسبير والمعطلة'!A4:A19) -> 16
A7: ⚠ المستندات التي تنتهي خلال 30 يومًا أو منتهية
A8: م | B8: الاسم | C8: رقم اللوحة | D8: نوع المستند | E8: تاريخ الانتهاء | F8: الأيام المتبقية
A9: =IF($G9="","",1) -> 1 | B9: =IF($G9="","",INDEX(بيانات_الربط!$A$2:$A$175,MATCH($G9,بيانات_الربط!$F$2:$F$175,0))) -> جيفري كريس | C9: =IF($G9="","",INDEX(بيانات_الربط!$B$2:$B$175,MATCH($G9,بيانات_الربط!$F$2:$F$175,0))) -> أ و ب 2759 | D9: =IF($G9="","",INDEX(بيانات_الربط!$C$2:$C$175,MATCH($G9,بيانات_الربط!$F$2:$F$175,0))) -> رخصة السير | E9: =IF($G9="","",INDEX(بيانات_الربط!$D$2:$D$175,MATCH($G9,بيانات_الربط!$F$2:$F$175,0))) -> 45970 | F9: =IF($G9="","",INDEX(بيانات_الربط!$E$2:$E$175,MATCH($G9,بيانات_الربط!$F$2:$F$175,0))) -> -291 | G9: =IFERROR(SMALL(بيانات_الربط!$F$2:$F$175,1),"") -> -290.99851
A10: =IF($G10="","",2) -> 2 | B10: =IF($G10="","",INDEX(بيانات_الربط!$A$2:$A$175,MATCH($G10,بيانات_الربط!$F$2:$F$175,0))) -> حسام الدين ابوالمجد | C10: =IF($G10="","",INDEX(بيانات_الربط!$B$2:$B$175,MATCH($G10,بيانات_الربط!$F$2:$F$175,0))) -> ب ص ط 9959 | D10: =IF($G10="","",INDEX(بيانات_الربط!$C$2:$C$175,MATCH($G10,بيانات_الربط!$F$2:$F$175,0))) -> الفحص الدوري | E10: =IF($G10="","",INDEX(بيانات_الربط!$D$2:$D$175,MATCH($G10,بيانات_الربط!$F$2:$F$175,0))) -> 46177 | F10: =IF($G10="","",INDEX(بيانات_الربط!$E$2:$E$175,MATCH($G10,بيانات_الربط!$F$2:$F$175,0))) -> -84 | G10: =IFERROR(SMALL(بيانات_الربط!$F$2:$F$175,2),"") -> -83.99869
A11: =IF($G11="","",3) -> 3 | B11: =IF($G11="","",INDEX(بيانات_الربط!$A$2:$A$175,MATCH($G11,بيانات_الربط!$F$2:$F$175,0))) -> كابيل مياه | C11: =IF($G11="","",INDEX(بيانات_الربط!$B$2:$B$175,MATCH($G11,بيانات_الربط!$F$2:$F$175,0))) -> ا س ح 8714 | D11: =IF($G11="","",INDEX(بيانات_الربط!$C$2:$C$175,MATCH($G11,بيانات_الربط!$F$2:$F$175,0))) -> بطاقة السائق | E11: =IF($G11="","",INDEX(بيانات_الربط!$D$2:$D$175,MATCH($G11,بيانات_الربط!$F$2:$F$175,0))) -> 46198 | F11: =IF($G11="","",INDEX(بيانات_الربط!$E$2:$E$175,MATCH($G11,بيانات_الربط!$F$2:$F$175,0))) -> -63 | G11: =IFERROR(SMALL(بيانات_الربط!$F$2:$F$175,3),"") -> -62.99935
A12: =IF($G12="","",4) -> 4 | B12: =IF($G12="","",INDEX(بيانات_الربط!$A$2:$A$175,MATCH($G12,بيانات_الربط!$F$2:$F$175,0))) -> انفير كاريماري عمير | C12: =IF($G12="","",INDEX(بيانات_الربط!$B$2:$B$175,MATCH($G12,بيانات_الربط!$F$2:$F$175,0))) -> أ س ر 8873 | D12: =IF($G12="","",INDEX(بيانات_الربط!$C$2:$C$175,MATCH($G12,بيانات_الربط!$F$2:$F$175,0))) -> رخصة السير | E12: =IF($G12="","",INDEX(بيانات_الربط!$D$2:$D$175,MATCH($G12,بيانات_الربط!$F$2:$F$175,0))) -> 46221 | F12: =IF($G12="","",INDEX(بيانات_الربط!$E$2:$E$175,MATCH($G12,بيانات_الربط!$F$2:$F$175,0))) -> -40 | G12: =IFERROR(SMALL(بيانات_الربط!$F$2:$F$175,4),"") -> -39.99959
A13: =IF($G13="","",5) -> 5 | B13: =IF($G13="","",INDEX(بيانات_الربط!$A$2:$A$175,MATCH($G13,بيانات_الربط!$F$2:$F$175,0))) -> جمال الدين محمد يوسف | C13: =IF($G13="","",INDEX(بيانات_الربط!$B$2:$B$175,MATCH($G13,بيانات_الربط!$F$2:$F$175,0))) -> أ ر ه 3213 | D13: =IF($G13="","",INDEX(بيانات_الربط!$C$2:$C$175,MATCH($G13,بيانات_الربط!$F$2:$F$175,0))) -> رخصة السير | E13: =IF($G13="","",INDEX(بيانات_الربط!$D$2:$D$175,MATCH($G13,بيانات_الربط!$F$2:$F$175,0))) -> 46225 | F13: =IF($G13="","",INDEX(بيانات_الربط!$E$2:$E$175,MATCH($G13,بيانات_الربط!$F$2:$F$175,0))) -> -36 | G13: =IFERROR(SMALL(بيانات_الربط!$F$2:$F$175,5),"") -> -35.99846
A14: =IF($G14="","",6) -> 6 | B14: =IF($G14="","",INDEX(بيانات_الربط!$A$2:$A$175,MATCH($G14,بيانات_الربط!$F$2:$F$175,0))) -> حسين مياه | C14: =IF($G14="","",INDEX(بيانات_الربط!$B$2:$B$175,MATCH($G14,بيانات_الربط!$F$2:$F$175,0))) -> ب ط س 3261 | D14: =IF($G14="","",INDEX(بيانات_الربط!$C$2:$C$175,MATCH($G14,بيانات_الربط!$F$2:$F$175,0))) -> رخصة السير | E14: =IF($G14="","",INDEX(بيانات_الربط!$D$2:$D$175,MATCH($G14,بيانات_الربط!$F$2:$F$175,0))) -> 46232 | F14: =IF($G14="","",INDEX(بيانات_الربط!$E$2:$E$175,MATCH($G14,بيانات_الربط!$F$2:$F$175,0))) -> -29 | G14: =IFERROR(SMALL(بيانات_الربط!$F$2:$F$175,6),"") -> -28.99839
A15: =IF($G15="","",7) -> 7 | B15: =IF($G15="","",INDEX(بيانات_الربط!$A$2:$A$175,MATCH($G15,بيانات_الربط!$F$2:$F$175,0))) -> حمداني كومفا ليميغاس | C15: =IF($G15="","",INDEX(بيانات_الربط!$B$2:$B$175,MATCH($G15,بيانات_الربط!$F$2:$F$175,0))) -> ب ط س 3258 | D15: =IF($G15="","",INDEX(بيانات_الربط!$C$2:$C$175,MATCH($G15,بيانات_الربط!$F$2:$F$175,0))) -> رخصة السير | E15: =IF($G15="","",INDEX(بيانات_الربط!$D$2:$D$175,MATCH($G15,بيانات_الربط!$F$2:$F$175,0))) -> 46232 | F15: =IF($G15="","",INDEX(بيانات_الربط!$E$2:$E$175,MATCH($G15,بيانات_الربط!$F$2:$F$175,0))) -> -29 | G15: =IFERROR(SMALL(بيانات_الربط!$F$2:$F$175,7),"") -> -28.99837
A19: موصل | B19: =COUNTIF('سجل النقل'!E5:E33,"موصل") -> 17
A20: موزع | B20: =COUNTIF('سجل النقل'!E5:E33,"موزع") -> 12
A21: ايسوزو دينا | B21: =COUNTIF('سجل النقل'!H5:H33,"ايسوزو دينا") -> 4
A22: ايسوزو لوري | B22: =COUNTIF('سجل النقل'!H5:H33,"ايسوزو لوري") -> 13
A23: متسوبيشي دينا | B23: =COUNTIF('سجل النقل'!H5:H33,"متسوبيشي دينا") -> 8
A24: متسوبيشي لوري | B24: =COUNTIF('سجل النقل'!H5:H33,"متسوبيشي لوري") -> 3
A25: هينو دينا | B25: =COUNTIF('سجل النقل'!H5:H33,"هينو دينا") -> 1
A27: اعداد / ادارة قسم الحركة

Sheet سجل النقل
A1: جدول تحديث المركبات والسائقين الأسبوعي (النقل العام) - فرع الدمام 2026
A2: تاريخ آخر تحديث: | T2: =TODAY() -> 46261 | U2: تاريخ اليوم:
A4: م | B4: الرقم الوظيفي | C4: اسم السائق | D4: رقم الإقامة | E4: الوظيفة | F4: رقم اللوحة | G4: الموديل | H4: نوع المركبة | I4: عدد الطبالي | J4: الحمولة | K4: الرقم التسلسلي | L4: تاريخ انتهاء الفحص الدوري | M4: الأيام المتبقية | N4: تاريخ انتهاء رخصة السير | O4: الأيام المتبقية | P4: تاريخ انتهاء بطاقة السائق | Q4: الأيام المتبقية | R4: تاريخ انتهاء بطاقة التشغيل | S4: الأيام المتبقية | T4: الملاحظات | U4: رقم الجوال
A5: 1 | B5: 100310 | C5: شمون مياه ادريس مياه | D5: 2253252916 | E5: موصل | F5: ا س م 8013 | G5: 2023 | H5: ايسوزو لوري | I5: 8 | J5: 3 | K5: 17554020 | L5: 46478 | M5: =IF(ISNUMBER(L5),L5-TODAY(),"-") -> 217 | N5: 46397 | O5: =IF(ISNUMBER(N5),N5-TODAY(),"-") -> 136 | P5: 46515 | Q5: =IF(ISNUMBER(P5),P5-TODAY(),"-") -> 254 | R5: 46479 | S5: =IF(ISNUMBER(R5),R5-TODAY(),"-") -> 218 | T5: لا يوجد | U5: 504125217
A6: 2 | B6: 100276 | C6: مد سيف | D6: 2485516401 | E6: موزع | F6: أ س م 8025 | G6: 2023 | H6: ايسوزو لوري | I6: 8 | J6: 3 | K6: 968754020 | L6: 46309 | M6: =IF(ISNUMBER(L6),L6-TODAY(),"-") -> 48 | N6: 46398 | O6: =IF(ISNUMBER(N6),N6-TODAY(),"-") -> 137 | P6: 46515 | Q6: =IF(ISNUMBER(P6),P6-TODAY(),"-") -> 254 | R6: 46484 | S6: =IF(ISNUMBER(R6),R6-TODAY(),"-") -> 223 | T6: لا يوجد | U6: 535690637
A7: 3 | B7: 100327 | C7: محمد عبدالصبور عبدالعزيز | D7: 2283628259 | E7: موصل | F7: ا س م 8024 | G7: 2023 | H7: ايسوزو لوري | I7: 8 | J7: 3 | K7: 358754020 | L7: 46309 | M7: =IF(ISNUMBER(L7),L7-TODAY(),"-") -> 48 | N7: 46398 | O7: =IF(ISNUMBER(N7),N7-TODAY(),"-") -> 137 | P7: 46515 | Q7: =IF(ISNUMBER(P7),P7-TODAY(),"-") -> 254 | R7: 46505 | S7: =IF(ISNUMBER(R7),R7-TODAY(),"-") -> 244 | T7: لا يوجد | U7: 565369080
A8: 4 | B8: 100245 | C8: كابيل مياه | D8: 2121612820 | E8: موزع | F8: ا س ح 8714 | G8: 2023 | H8: متسوبيشي دينا | I8: 4 | J8: 3 | K8: 29819910 | L8: 46295 | M8: =IF(ISNUMBER(L8),L8-TODAY(),"-") -> 34 | N8: 47192 | O8: =IF(ISNUMBER(N8),N8-TODAY(),"-") -> 931 | P8: 46198 | Q8: =IF(ISNUMBER(P8),P8-TODAY(),"-") -> -63 | R8: 46515 | S8: =IF(ISNUMBER(R8),R8-TODAY(),"-") -> 254 | T8: لم يتم التجديد -اصدار رخصة نقل ثقيل | U8: 567116916
A9: 5 | B9: 102179 | C9: تنفير حسين | D9: 2519784710 | E9: موصل | F9: ا ر ع 2234 | G9: 2020 | H9: متسوبيشي دينا | I9: 4 | J9: 3 | K9: 196860810 | L9: 46563 | M9: =IF(ISNUMBER(L9),L9-TODAY(),"-") -> 302 | N9: 46272 | O9: =IF(ISNUMBER(N9),N9-TODAY(),"-") -> 11 | P9: 46515 | Q9: =IF(ISNUMBER(P9),P9-TODAY(),"-") -> 254 | R9: 46515 | S9: =IF(ISNUMBER(R9),R9-TODAY(),"-") -> 254 | T9: لايوجد | U9: 594535961
A10: 6 | B10: 102181 | C10: محمد مصلح حمادي محسن | D10: 2536883693 | E10: موزع | F10: ا ر و 4140 | G10: 2023 | H10: ايسوزو لوري | I10: 8 | J10: 3 | K10: 826065910 | L10: 46475 | M10: =IF(ISNUMBER(L10),L10-TODAY(),"-") -> 214 | N10: 46997 | O10: =IF(ISNUMBER(N10),N10-TODAY(),"-") -> 736 | P10: 46505 | Q10: =IF(ISNUMBER(P10),P10-TODAY(),"-") -> 244 | R10: 46515 | S10: =IF(ISNUMBER(R10),R10-TODAY(),"-") -> 254 | T10: لايوجد | U10: 548827398
A11: 7 | B11: 100217 | C11: مارييل فينود | D11: 2501620039 | E11: موصل | F11: ا س 8015 | G11: 2023 | H11: ايسوزو لوري | I11: 8 | J11: 2 | K11: 698454020 | L11: 46536 | M11: =IF(ISNUMBER(L11),L11-TODAY(),"-") -> 275 | N11: 46398 | O11: =IF(ISNUMBER(N11),N11-TODAY(),"-") -> 137 | P11: 46528 | Q11: =IF(ISNUMBER(P11),P11-TODAY(),"-") -> 267 | R11: 46485 | S11: =IF(ISNUMBER(R11),R11-TODAY(),"-") -> 224 | T11: لايوجد | U11: 564915114
A12: 8 | B12: 102452 | C12: محمد يونس | D12: 2550977850 | E12: موصل | F12: ا س ق 7776 | G12: 2016 | H12: متسوبيشي لوري | I12: 8 | J12: 2 | K12: 831809610 | L12: 46384 | M12: =IF(ISNUMBER(L12),L12-TODAY(),"-") -> 123 | N12: 46282 | O12: =IF(ISNUMBER(N12),N12-TODAY(),"-") -> 21 | P12: 46516 | Q12: =IF(ISNUMBER(P12),P12-TODAY(),"-") -> 255 | R12: 46515 | S12: =IF(ISNUMBER(R12),R12-TODAY(),"-") -> 254 | T12: لايوجد | U12: 575806817
A13: 9 | B13: 100360 | C13: ابراهيم محمد ابوزيد محمد | D13: 2393652496 | E13: موزع | F13: ا ر ع 2232 | G13: 2023 | H13: متسوبيشي دينا | I13: 4 | J13: 3 | K13: 386860810 | L13: 46521 | M13: =IF(ISNUMBER(L13),L13-TODAY(),"-") -> 260 | N13: 46265 | O13: =IF(ISNUMBER(N13),N13-TODAY(),"-") -> 4 | P13: 46515 | Q13: =IF(ISNUMBER(P13),P13-TODAY(),"-") -> 254 | R13: 46515 | S13: =IF(ISNUMBER(R13),R13-TODAY(),"-") -> 254 | T13: لايوجد | U13: 541364538
A14: 10 | B14: 100332 | C14: انفير كاريماري عمير | D14: 2350147415 | E14: موزع | F14: أ س ر 8873 | G14: 2020 | H14: متسوبيشي دينا | I14: 4 | J14: 3 | K14: 203480020 | L14: 46296 | M14: =IF(ISNUMBER(L14),L14-TODAY(),"-") -> 35 | N14: 46221 | O14: =IF(ISNUMBER(N14),N14-TODAY(),N14-"") -> -40 | P14: 46513 | Q14: =IF(ISNUMBER(P14),P14-TODAY(),"-") -> 252 | R14: 46515 | S14: =IF(ISNUMBER(R14),R14-TODAY(),"-") -> 254 | T14: لا يوجد | U14: 571991926
A15: 11 | B15: 102126 | C15: ارجوان | D15: 2530207360 | E15: موزع | F15: ا س م 8033 | G15: 2023 | H15: ايسوزو لوري | I15: 8 | J15: 3 | K15: 207954020 | L15: 46478 | M15: =IF(ISNUMBER(L15),L15-TODAY(),"-") -> 217 | N15: 46398 | O15: =IF(ISNUMBER(N15),N15-TODAY(),"-") -> 137 | P15: 46515 | Q15: =IF(ISNUMBER(P15),P15-TODAY(),"-") -> 254 | R15: 46485 | S15: =IF(ISNUMBER(R15),R15-TODAY(),"-") -> 224 | T15: لا يوجد | U15: 567948210
A16: 12 | B16: 100828 | C16: اجيت راجا | D16: 2461544377 | E16: موزع | F16: ا ر و 4084 | G16: 2022 | H16: ايسوزو دينا | I16: 4 | J16: 3 | K16: 960941910 | L16: 46384 | M16: =IF(ISNUMBER(L16),L16-TODAY(),"-") -> 123 | N16: 46858 | O16: =IF(ISNUMBER(N16),N16-TODAY(),"-") -> 597 | P16: 46388 | Q16: =IF(ISNUMBER(P16),P16-TODAY(),"-") -> 127 | R16: 46379 | S16: =IF(ISNUMBER(R16),R16-TODAY(),"-") -> 118 | T16: لايوجد | U16: 549131428
A17: 13 | B17: 100522 | C17: سليم اختر محمد | D17: 2430898482 | E17: موزع | F17: ا س ح 8670 | G17: 2023 | H17: متسوبيشي دينا | I17: 4 | J17: 3 | K17: 379167910 | L17: 46338 | M17: =IF(ISNUMBER(L17),L17-TODAY(),"-") -> 77 | N17: 47153 | O17: =IF(ISNUMBER(N17),N17-TODAY(),"-") -> 892 | P17: 46296 | Q17: =IF(ISNUMBER(P17),P17-TODAY(),"-") -> 35 | R17: 46515 | S17: =IF(ISNUMBER(R17),R17-TODAY(),"-") -> 254 | T17: لايوجد | U17: 581993668
A18: 14 | B18: 100711 | C18: احمد رشوان | D18: 2409104953 | E18: موصل | F18: ا ص ق 6853 | G18: 2024 | H18: ايسوزو دينا | I18: 4 | J18: 3 | K18: 739131120 | L18: 46476 | M18: =IF(ISNUMBER(L18),L18-TODAY(),"-") -> 215 | N18: 46583 | O18: =IF(ISNUMBER(N18),N18-TODAY(),"-") -> 322 | P18: 46330 | Q18: =IF(ISNUMBER(P18),P18-TODAY(),"-") -> 69 | R18: 46505 | S18: =IF(ISNUMBER(R18),R18-TODAY(),"-") -> 244 | T18: لايوجد | U18: 567428582
A19: 15 | B19: 100330 | C19: اسف باث شوهل | D19: 2325599070 | E19: موزع | F19: ا س ح 8717 | G19: 2023 | H19: متسوبيشي دينا | I19: 4 | J19: 3 | K19: 949819910 | L19: 46467 | M19: =IF(ISNUMBER(L19),L19-TODAY(),"-") -> 206 | N19: 47192 | O19: =IF(ISNUMBER(N19),N19-TODAY(),"-") -> 931 | P19: 46417 | Q19: =IF(ISNUMBER(P19),P19-TODAY(),"-") -> 156 | R19: 46515 | S19: =IF(ISNUMBER(R19),R19-TODAY(),"-") -> 254 | T19: لايوجد | U19: 571724688
A20: 16 | B20: 100303 | C20: فالق سجاد سجاد | D20: 2090207859 | E20: موصل | F20: ا س م 8029 | G20: 2023 | H20: ايسوزو لوري | I20: 8 | J20: 3 | K20: 537954020 | L20: 46474 | M20: =IF(ISNUMBER(L20),L20-TODAY(),"-") -> 213 | N20: 46398 | O20: =IF(ISNUMBER(N20),N20-TODAY(),"-") -> 137 | P20: 46386 | Q20: =IF(ISNUMBER(P20),P20-TODAY(),"-") -> 125 | R20: 46479 | S20: =IF(ISNUMBER(R20),R20-TODAY(),"-") -> 218 | T20: لايوجد | U20: 558453231
A21: 17 | B21: 102845 | C21: موزيد خان | D21: 2607260698 | E21: موصل | F21: ا س ل 8850 | G21: 2016 | H21: متسوبيشي لوري | I21: 8 | J21: 2 | K21: 451809610 | L21: 46348 | M21: =IF(ISNUMBER(L21),L21-TODAY(),"-") -> 87 | N21: 46303 | O21: =IF(ISNUMBER(N21),N21-TODAY(),"-") -> 42 | P21: 46515 | Q21: =IF(ISNUMBER(P21),P21-TODAY(),"-") -> 254 | R21: 46515 | S21: =IF(ISNUMBER(R21),R21-TODAY(),"-") -> 254 | T21: لايوجد | U21: 572901340
A22: 18 | B22: 102368 | C22: بسام علي احمد الجلال | D22: 2537417152 | E22: موصل | F22: ا س م 8023 | G22: 2023 | H22: ايسوزو لوري | I22: 8 | J22: 3 | K22: 277754020 | L22: 46310 | M22: =IF(ISNUMBER(L22),L22-TODAY(),"-") -> 49 | N22: 46398 | O22: =IF(ISNUMBER(N22),N22-TODAY(),"-") -> 137 | P22: 46500 | Q22: =IF(ISNUMBER(P22),P22-TODAY(),"-") -> 239 | R22: 46484 | S22: =IF(ISNUMBER(R22),R22-TODAY(),"-") -> 223 | T22: لايوجد | U22: 536735114
A23: 19 | B23: 101260 | C23: كرم ابو الهدى صادق | D23: 2487345031 | E23: موزع | F23: ا ر و 4071 | G23: 2022 | H23: ايسوزو دينا | I23: 4 | J23: 3 | K23: 74841910 | L23: 46359 | M23: =IF(ISNUMBER(L23),L23-TODAY(),"-") -> 98 | N23: 46858 | O23: =IF(ISNUMBER(N23),N23-TODAY(),"-") -> 597 | P23: 46504 | Q23: =IF(ISNUMBER(P23),P23-TODAY(),"-") -> 243 | R23: 46379 | S23: =IF(ISNUMBER(R23),R23-TODAY(),"-") -> 118 | T23: لايوجد | U23: 564649987
A24: 20 | B24: 101936 | C24: مران حسين مد تارو | D24: 2505074498 | E24: موصل | F24: ا س م 8031 | G24: 2023 | H24: ايسوزو لوري | I24: 8 | J24: 3 | K24: 317954020 | L24: 46476 | M24: =IF(ISNUMBER(L24),L24-TODAY(),"-") -> 215 | N24: 46398 | O24: =IF(ISNUMBER(N24),N24-TODAY(),"-") -> 137 | P24: 46515 | Q24: =IF(ISNUMBER(P24),P24-TODAY(),"-") -> 254 | R24: 46485 | S24: =IF(ISNUMBER(R24),R24-TODAY(),"-") -> 224 | T24: لايوجد | U24: 550920461
A25: 21 | B25: 100717 | C25: محمد عبدالحميد محمد | D25: 2445181585 | E25: موزع | F25: ا س م 8035 | G25: 2023 | H25: ايسوزو لوري | I25: 8 | J25: 3 | K25: 776954020 | L25: 46480 | M25: =IF(ISNUMBER(L25),L25-TODAY(),"-") -> 219 | N25: 46398 | O25: =IF(ISNUMBER(N25),N25-TODAY(),"-") -> 137 | P25: 46515 | Q25: =IF(ISNUMBER(P25),P25-TODAY(),"-") -> 254 | R25: 46505 | S25: =IF(ISNUMBER(R25),R25-TODAY(),"-") -> 244 | T25: لايوجد | U25: 564701656
A26: 22 | B26: 100711 | C26: احمد عبدالصبور رشوان | D26: 2409104953 | E26: موصل | F26: ا س م 8021 | G26: 2023 | H26: ايسوزو لوري | I26: 8 | J26: 3 | K26: 538754020 | L26: 46321 | M26: =IF(ISNUMBER(L26),L26-TODAY(),"-") -> 60 | N26: 46398 | O26: =IF(ISNUMBER(N26),N26-TODAY(),"-") -> 137 | P26: 46515 | Q26: =IF(ISNUMBER(P26),P26-TODAY(),"-") -> 254 | R26: 46505 | S26: =IF(ISNUMBER(R26),R26-TODAY(),"-") -> 244 | T26: لايوجد | U26: 567428582
... A33: 29 | B33: 100574 | C33: محمد عبدالرحمن السيد المندوه | D33: 2441077944 | E33: موزع | F33: أ ص ق 6855 | G33: 2024 | H33: ايسوزو دينا | I33: 4 | J33: 3 | K33: 761431120 | L33: 46478 | M33: =IF(ISNUMBER(L33),L33-TODAY(),"-") -> 217 | N33: 46592 | O33: =IF(ISNUMBER(N33),N33-TODAY(),"-") -> 331 | P33: 46543 | Q33: =IF(ISNUMBER(P33),P33-TODAY(),"-") -> 282 | R33: 46515 | S33: =IF(ISNUMBER(R33),R33-TODAY(),"-") -> 254 | T33: لايوجد | U33: 576559794

Sheet معلومات سائقون النقل العام
A1: م | B1: اسم السائق | C1: رقم الإقامة | D1: تاريخ الميلاد
A2: 1 | B2: احمد رضا فتوح العليمى | C2: 2431684956 | D2: 1994-09-05
A3: 2 | B3: النور علي | C3: 2553134111 | D3: 1997-10-27
A4: 3 | B4: مانودينغ ديلوسان راسيد | C4: 2515391890 | D4: 1990-11-13
A5: 4 | B5: محمد باشا | C5: 2402596973 | D5: 1985-04-03
A6: 5 | B6: جيفري كريس | C6: 2427982562 | D6: 1987-08-27
A7: 6 | B7: امين عبدالله احمد العاقل | C7: 2192810774 | D7: 1980-01-01
A8: 7 | B8: حمداني كومفا ليميغاس | C8: 2553132479 | D8: 1996-12-26
A9: 8 | B9: محمد عاطف محمد محمد | C9: 2460016781 | D9: 1988-11-28
A10: 9 | B10: حسام الدين محمد على ابوالمجد | C10: 2459346280 | D10: 1980-07-28
A11: 10 | B11: حسين مياه | C11: 2505074399 | D11: 1999-01-01
A12: 11 | B12: مأمون مياه | C12: 2508752892 | D12: 1990-04-19
A13: 12 | B13: عمر سمان ناتانكوف | C13: 2515391718 | D13: 1989-03-12
... A17: 16 | B17: كرم ابوالهدى صادق عبدالكريم | C17: 2487345031 | D17: 1985-06-06
A18: 17 | B18: اجيت راجا | C18: 2461544377 | D18: 33263
A19: 18 | B19: على محمد ابوزيد محمد | C19: 2441374739 | D19: 1981-02-01
A20: 19 | B20: احمد عبدالصبور محمود رشوان | C20: 2409104953 | D20: 1994-10-17
A21: 20 | B21: انفير كاريماري عمير | C21: 2350147415 | D21: 1975-04-07
A22: 21 | B22: محمد عبدالصبور عبدالعزيز سلام | C22: 2283628259 | D22: 1970-10-09
A23: 22 | B23: علاء عبد النبي رفاعي احمد | C23: 2327676793 | D23: 1990-01-09
A24: 23 | B24: موزايد خان | C24: 2607260698 | D24: 2003-01-02
A25: 24 | B25: ارجوان ارجوان | C25: 2530207360 | D25: 1982-07-16
A26: 25 | B26: عمران حسين مد تارو | C26: 2505074498 | D26: 1996-02-05
A27: 26 | B27: مد سيف الاسلام | C27: 2485516401 | D27: 1997-05-01
A28: 27 | B28: محمد عبدالنبى رفاعى احمد | C28: 2468851676 | D28: 1997-05-05
A29: 28 | B29: محمد عبد الحميد محمد مصطفى | C29: 2445181585 | D29: 1996-10-16
A30: 29 | B30: محمد عبدالرحمن السيد المندوه | C30: 2441077944 | D30: 1994-03-01
... A62: 61 | B62: احمد عبدالصبور محمد دنقل | C62: 2441375439 | D62: 1991-10-22

Sheet سجل الخاص
A1: جدول تحديث المركبات والسائقين الأسبوعي (النقل الخاص) - فرع الدمام 2026
A2: تاريخ آخر تحديث: | O2: =TODAY() -> 46261 | P2: تاريخ اليوم:
A4: م | B4: الرقم الوظيفي | C4: اسم السائق | D4: رقم الإقامة | E4: الوظيفة | F4: رقم اللوحة | G4: الموديل | H4: نوع المركبة | I4: الحمولة | J4: الرقم التسلسلي | K4: تاريخ انتهاء الفحص الدوري | L4: الأيام المتبقية | M4: تاريخ انتهاء رخصة السير | N4: الأيام المتبقية | O4: الملاحظات | P4: رقم الجوال
A5: 1 | B5: 100712 | C5: جيفري كريس | D5: 2427982562 | E5: مصفف | F5: أ و ب 2759 | G5: 2013 | H5: بكب غمارتين | J5: 91202310 | K5: 46368 | L5: =IF(ISNUMBER(K5),K5-TODAY(),"-") -> 107 | M5: 45970 | N5: =IF(ISNUMBER(M5),M5-TODAY(),"-") -> -291 | O5: صالحة | P5: 592619164
A6: 2 | B6: 100939 | C6: محمد باشا | D6: 2402596973 | E6: مصفف | F6: ب د ل 7208 | G6: 2018 | H6: بكب غمارتين | J6: 965759610 | K6: 46569 | L6: =IF(ISNUMBER(K6),K6-TODAY(),"-") -> 308 | M6: 46665 | N6: =IF(ISNUMBER(M6),M6-TODAY(),"-") -> 404 | O6: صالحة | P6: 595731324
A7: 3 | B7: 102816 | C7: احمد رضا فتوح العليمى | D7: 2431684956 | E7: مندوب جملة | F7: ب ب ق 4866 | G7: 2016 | H7: بكب غمارتين | J7: 601482510 | K7: 46527 | L7: =IF(ISNUMBER(K7),K7-TODAY(),"-") -> 266 | M7: 46754 | N7: =IF(ISNUMBER(M7),M7-TODAY(),"-") -> 493 | O7: صالحة | P7: 592312195
A8: 4 | B8: 102324 | C8: النور علي | D8: 2553134111 | E8: مصفف | F8: أ و ب 2760 | G8: 2013 | H8: بكب غمارتين | J8: 512202310 | K8: 46358 | L8: =IF(ISNUMBER(K8),K8-TODAY(),"-") -> 97 | M8: 47033 | N8: =IF(ISNUMBER(M8),M8-TODAY(),"-") -> 772 | O8: صالحة | P8: 571082341
A9: 5 | B9: 101866 | C9: مانودينغ ديلوسان راسيد | D9: 2515391890 | E9: مصفف | F9: ب ب ق 4868 | G9: 2016 | H9: بكب غمارتين | J9: 912482510 | K9: 46354 | L9: =IF(ISNUMBER(K9),K9-TODAY(),"-") -> 93 | M9: 46754 | N9: =IF(ISNUMBER(M9),M9-TODAY(),"-") -> 493 | O9: صالحة | P9: 570157523
A10: 6 | B10: 100982 | C10: جمال الدين محمد يوسف | D10: 2465265227 | E10: ميكانيكي | F10: أ ر ه 3213 | G10: 2009 | H10: بكب غمارتين | J10: 619501900 | K10: 46545 | L10: =IF(ISNUMBER(K10),K10-TODAY(),"-") -> 284 | M10: 46225 | N10: =IF(ISNUMBER(M10),M10-TODAY(),"-") -> -36 | O10: صالحة | P10: 544767971
A11: 7 | B11: 100321 | C11: امين عبدالله احمد العاقل | D11: 2192810774 | E11: مندوب جملة | F11: ب ط س 3417 | G11: 2023 | H11: بكب غمارتين | J11: 885442020 | K11: 46314 | L11: =IF(ISNUMBER(K11),K11-TODAY(),"-") -> 53 | M11: 46280 | N11: =IF(ISNUMBER(M11),M11-TODAY(),"-") -> 19 | O11: صالحة | P11: 533858352
A12: 8 | B12: 101867 | C12: النور امفوان ساري | D12: 2515391791 | E12: مصفف | F12: ب ر ل 3099 | G12: 2020 | H12: بكب غمارتين | J12: 174535710 | K12: 46577 | L12: =IF(ISNUMBER(K12),K12-TODAY(),"-") -> 316 | M12: 47000 | N12: =IF(ISNUMBER(M12),M12-TODAY(),"-") -> 739 | O12: صالحة | P12: 570601213
A13: 9 | B13: 102872 | C13: FAHAD BENASING LOMINOG | D13: 2567970229 | E13: مصفف | F13: ب ر ل 3098 | G13: 2020 | H13: بكب غمارتين | J13: 644535710 | K13: 46533 | L13: =IF(ISNUMBER(K13),K13-TODAY(),"-") -> 272 | M13: 47000 | N13: =IF(ISNUMBER(M13),M13-TODAY(),"-") -> 739 | O13: صالحة | P13: 570513092
A14: 10 | B14: 102064 | C14: حسام الدين ابوالمجد | D14: 2459346280 | E14: مندوب جملة | F14: ب ص ط 9959 | G14: 2022 | H14: بكب غماره | J14: 94714910 | K14: 46177 | L14: =IF(ISNUMBER(K14),K14-TODAY(),"-") -> -84 | M14: 46985 | N14: =IF(ISNUMBER(M14),M14-TODAY(),"-") -> 724 | O14: سليم - جاهز للعمل | P14: 510138281
A15: 11 | B15: 102135 | C15: احمد رشاد | D15: 2533532608 | E15: محاسب عملاء | F15: ح ع ن 2874 | G15: 2015 | H15: كورولا | J15: 812220410 | K15: 46346 | L15: =IF(ISNUMBER(K15),K15-TODAY(),"-") -> 85 | M15: 46286 | N15: =IF(ISNUMBER(M15),M15-TODAY(),"-") -> 25 | O15: صالحة | P15: 545909596
A16: 12 | B16: 102657 | C16: كرم جلال الدين | D16: 2578319739 | E16: مدير مبيعات | F16: ر د ب 4650 | G16: 2022 | H16: جيب فورتشنر | J16: 317833910 | K16: 46416 | L16: =IF(ISNUMBER(K16),K16-TODAY(),"-") -> 155 | M16: 46949 | N16: =IF(ISNUMBER(M16),M16-TODAY(),"-") -> 688 | O16: صالحة | P16: 546008439
A17: 13 | B17: 101937 | C17: حسين مياه | D17: 2505074399 | E17: عامل | F17: ب ط س 3261 | G17: 2023 | H17: بكب غماره | J17: 442111020 | K17: 46394 | L17: =IF(ISNUMBER(K17),K17-TODAY(),"-") -> 133 | M17: 46232 | N17: =IF(ISNUMBER(M17),M17-TODAY(),"-") -> -29 | O17: صالحة | P17: 548641880
A18: 14 | B18: 102911 | C18: عبد الحكيم جمال عبد الحكيم احمد | D18: 2620311569 | E18: مندوب جمله | F18: ب ط س 3262 | G18: 2023 | H18: بكب غماره | J18: 662111020 | K18: 46613 | L18: =IF(ISNUMBER(K18),K18-TODAY(),"-") -> 352 | M18: 47295 | N18: =IF(ISNUMBER(M18),M18-TODAY(),"-") -> 1034 | O18: صالحة | P18: 551887509"
A19: 15 | B19: 102325 | C19: حمداني كومفا ليميغاس | D19: 2553132479 | E19: مصفف | F19: ب ط س 3258 | G19: 2023 | H19: بكب غماره | J19: 661111020 | K19: 46306 | L19: =IF(ISNUMBER(K19),K19-TODAY(),"-") -> 45 | M19: 46232 | N19: =IF(ISNUMBER(M19),M19-TODAY(),"-") -> -29 | O19: صالحة | P19: 570866459
A20: 16 | B20: 101864 | C20: عمر سمان ناتانكوف | D20: 2515391718 | E20: مصفف | F20: ب ط س 3259 | G20: 2023 | H20: بكب غماره | J20: 881111020 | K20: 46351 | L20: =IF(ISNUMBER(K20),K20-TODAY(),"-") -> 90 | M20: 46232 | N20: =IF(ISNUMBER(M20),M20-TODAY(),"-") -> -29 | O20: صالحة | P20: 570823597
A21: 17 | B21: 101932 | C21: مأمون مياه | D21: 2508752892 | E21: عامل | F21: ب ط س3263 | G21: 2023 | H21: بكب غماره | J21: 882111020 | K21: 46350 | L21: =IF(ISNUMBER(K21),K21-TODAY(),"-") -> 89 | M21: 46232 | N21: =IF(ISNUMBER(M21),M21-TODAY(),"-") -> -29 | O21: صالحة | P21: 543589466
A22: 18 | B22: 102964 | C22: SHAH ZEB | D22: 2616718371 | F22: ب ح ل 4436 | G22: 2020 | H22: تي 60 بيك اب | J22: 228047710 | K22: 46546 | L22: =IF(ISNUMBER(K22),K22-TODAY(),"-") -> 285 | M22: 47098 | N22: =IF(ISNUMBER(M22),M22-TODAY(),"-") -> 837 | O22: صالحة | P22: 501434981
A23: 19 | B23: 100363 | C23: ابراهيم يوسف عوض علي | D23: 2249251576 | E23: منسق مبيعات | F23: ح ي و 5746 | G23: 2016 | H23: سيراتيو | J23: 653965510 | K23: 46318 | L23: =IF(ISNUMBER(K23),K23-TODAY(),"-") -> 57 | M23: 46885 | N23: =IF(ISNUMBER(M23),M23-TODAY(),"-") -> 624 | O23: سليم - جاهز للعمل | P23: 561154830
A24: 20 | B24: 100364 | C24: أشرف كمال | D24: 2342453558 | E24: سكرتير | F24: ر و د 1693 | G24: 2025 | H24: DZIRE | J24: 966200220 | K24: - | L24: =IF(ISNUMBER(K24),K24-TODAY(),"-") -> - | M24: 46889 | N24: =IF(ISNUMBER(M24),M24-TODAY(),"-") -> 628 | O24: صالحة | P24: 552313697
A25: 21 | B25: 102369 | C25: كريم عبد المنعم | D25: 2516932148 | E25: مندوب جملة | F25: أ ص ه 6135 | G25: 2010 | H25: بكب غماره | J25: 264716900 | K25: 46615 | L25: =IF(ISNUMBER(K25),K25-TODAY(),"-") -> 354 | M25: 46503 | N25: =IF(ISNUMBER(M25),M25-TODAY(),"-") -> 242 | O25: صالحة | P25: 510269126
A26: 22 | B26: 102072 | C26: عبدالرحمن البنداري | D26: 2519087791 | E26: مشرف جملة | F26: ر ل ر 5062 | G26: 2024 | H26: ديز اير | J26: 709509020 | K26: - | L26: =IF(ISNUMBER(K26),K26-TODAY(),"-") -> - | M26: 46510 | N26: =IF(ISNUMBER(M26),M26-TODAY(),"-") -> 249 | O26: صالحة | P26: 545381775
A27: 23 | B27: 102824 | C27: احمد محمد زكى شعلان | D27: 2596889713 | F27: ر ل ر 5063 | G27: 2024 | H27: ديز اير | J27: 719509020 | K27: - | L27: =IF(ISNUMBER(K27),K27-TODAY(),"-") -> - | M27: 46510 | N27: =IF(ISNUMBER(M27),M27-TODAY(),"-") -> 249 | O27: صالحة | P27: 501486037
A28: 24 | B28: 102182 | C28: أبو الحسن | D28: 2532825581 | E28: مشرف جملة | F28: ر ل ر 5059 | G28: 2024 | H28: ديز اير | J28: 598509020 | K28: - | L28: =IF(ISNUMBER(K28),K28-TODAY(),"-") -> - | M28: 46510 | N28: =IF(ISNUMBER(M28),M28-TODAY(),"-") -> 249 | O28: صالحة | P28: 541619715
A29: 25 | B29: 102559 | C29: محمد تنوير | D29: 2207767803 | E29: مشرف سوبرماركت | F29: ر ل ر 5094 | G29: 2024 | H29: ديز اير | J29: 280609020 | K29: - | L29: =IF(ISNUMBER(K29),K29-TODAY(),"-") -> - | M29: 46510 | N29: =IF(ISNUMBER(M29),M29-TODAY(),"-") -> 249 | O29: صالحة | P29: 500321921
A30: 26 | B30: 101399 | C30: محمد حسن عبدالرحمن السيد | D30: 2494382019 | E30: مندوب ماركت | F30: س د ي 2475 | G30: 2026 | H30: BALENO | J30: 340707220 | K30: - | L30: =IF(ISNUMBER(K30),K30-TODAY(),"-") -> - | M30: 47125 | N30: =IF(ISNUMBER(M30),M30-TODAY(),"-") -> 864 | O30: صالحة | P30: 557307783
A31: 27 | B31: 102172 | C31: مهتاب الطاف الطاف احمد | D31: 2347224004 | E31: مندوب ماركت | F31: س د ي 2487 | G31: 2026 | H31: BALENO | J31: 841707220 | K31: - | L31: =IF(ISNUMBER(K31),K31-TODAY(),"-") -> - | M31: 47125 | N31: =IF(ISNUMBER(M31),M31-TODAY(),"-") -> 864 | O31: صالحة | P31: 541660773

Sheet الأسبير والمعطلة
A1: بيان المركبات الأسبير والمعطلة
A3: م | B3: الحالة | C3: رقم اللوحة | D3: الموديل | E3: نوع المركبة | F3: عدد الطبالي | G3: الحمولة | H3: الرقم التسلسلي | I3: السجل | J3: تاريخ انتهاء الفحص الدوري | K3: الأيام المتبقية | L3: تاريخ انتهاء رخصة السير | M3: الأيام المتبقية | N3: تاريخ انتهاء بطاقة التشغيل | O3: الأيام المتبقية | P3: الملاحظات
A4: 1 | B4: فحص | C4: ا س ق 7774 | D4: 2016 | E4: متسوبيشي لوري | F4: 8 | G4: 2 | H4: 178838410 | I4: 7017817896 | J4: 45978 | K4: =IF(ISNUMBER(J4),J4-TODAY(),"-") -> -283 | L4: 46284 | M4: =IF(ISNUMBER(L4),L4-TODAY(),"-") -> 23 | N4: 46159 | O4: =IF(ISNUMBER(N4),N4-TODAY(),"-") -> -102 | P4: لم يتم تجديد بطاقة التشغيل (فحص دوري- صيانة جهاز التتبع)
A5: 2 | B5: فحص | C5: ا س ق 7821 | D5: 2016 | E5: متسوبيشي لوري | F5: 8 | G5: 3 | H5: 787571510 | I5: 7017817896 | J5: 45993 | K5: =IF(ISNUMBER(J5),J5-TODAY(),"-") -> -268 | L5: 46291 | M5: =IF(ISNUMBER(L5),L5-TODAY(),"-") -> 30 | N5: 46159 | O5: =IF(ISNUMBER(N5),N5-TODAY(),"-") -> -102 | P5: لم يتم تجديد بطاقة التشغيل (فحص دوري- صيانة جهاز التتبع)
A6: 4 | B6: اسبير | C6: أ س ق 7775 | D6: 2016 | E6: متسوبيشي لوري | F6: 8 | G6: 2 | H6: 490809610 | I6: 7017817896 | J6: 46348 | K6: =IF(ISNUMBER(J6),J6-TODAY(),"-") -> 87 | L6: 46284 | M6: =IF(ISNUMBER(L6),L6-TODAY(),"-") -> 23 | N6: 46159 | O6: =IF(ISNUMBER(N6),N6-TODAY(),"-") -> -102 | P6: تحديد بطاقة التشغيل (صيانة جهاز التتبع)
A7: 5 | B7: معطلة | C7: أ س م 8022 | D7: 2023 | E7: ايسوزو لوري | F7: 8 | G7: 3 | H7: 978754020 | I7: 7017817896 | J7: لا يوجد | K7: =IF(ISNUMBER(J7),J7-TODAY(),"-") -> - | L7: 46398 | M7: =IF(ISNUMBER(L7),L7-TODAY(),"-") -> 137 | N7: 46118 | O7: =IF(ISNUMBER(N7),N7-TODAY(),"-") -> -143 | P7: فحص دوري - استكر - كرت تشغيل
A8: 6 | B8: معطلة | C8: ا ر و 4085 | D8: 2022 | E8: ايسوزو دينا | F8: 4 | G8: 3 | H8: 211941910 | I8: 7017817896 | J8: 46446 | K8: =IF(ISNUMBER(J8),J8-TODAY(),"-") -> 185 | L8: 46858 | M8: =IF(ISNUMBER(L8),L8-TODAY(),"-") -> 597 | N8: 46379 | O8: =IF(ISNUMBER(N8),N8-TODAY(),"-") -> 118 | P8: جربكس سوء استخدام
A9: 7 | B9: معطلة | C9: ا ر ل 5580 | D9: 2015 | E9: ايسوزو دينا | F9: 4 | G9: 3 | H9: 322761410 | I9: 7017817896 | J9: 46552 | K9: =IF(ISNUMBER(J9),J9-TODAY(),"-") -> 291 | L9: 46553 | M9: =IF(ISNUMBER(L9),L9-TODAY(),"-") -> 292 | N9: 46515 | O9: =IF(ISNUMBER(N9),N9-TODAY(),"-") -> 254 | P9: اصلاح صندوق
A10: 8 | B10: اسبير | C10: ب ص ب 5125 | D10: 2022 | E10: فان | F10: - | G10: - | H10: 766440910 | I10: 7000473079 | J10: 46044 | K10: =IF(ISNUMBER(J10),J10-TODAY(),"-") -> -217 | L10: 46790 | M10: =IF(ISNUMBER(L10),L10-TODAY(),"-") -> 529 | N10: - | O10: =IF(ISNUMBER(N10),N10-TODAY(),"-") -> - | P10: صالحة
A11: 9 | B11: اسبير | C11: د د و 4282 | D11: 2018 | E11: اكسنت | F11: - | G11: - | H11: 679743610 | I11: 7000473079 | J11: 46323 | K11: =IF(ISNUMBER(J11),J11-TODAY(),"-") -> 62 | L11: 46260 | M11: =IF(ISNUMBER(L11),L11-TODAY(),"-") -> -1 | N11: - | O11: =IF(ISNUMBER(N11),N11-TODAY(),"-") -> - | P11: صالحة
A12: 10 | B12: معطلة | C12: ب د ل 7207 | D12: 2018 | E12: بكب غمارتين | F12: - | G12: - | H12: 305759610 | I12: 7000473079 | J12: 46560 | K12: =IF(ISNUMBER(J12),J12-TODAY(),"-") -> 299 | L12: 46665 | M12: =IF(ISNUMBER(L12),L12-TODAY(),"-") -> 404 | N12: - | O12: =IF(ISNUMBER(N12),N12-TODAY(),"-") -> - | P12: عطل ميكانيكي - مشكلة في المحرك
A13: 11 | B13: معطلة | C13: أ ر ه 2769 | D13: 2009 | E13: بكب غمارتين | F13: - | G13: - | H13: 12052900 | I13: 7000473079 | J13: 46164 | K13: =IF(ISNUMBER(J13),J13-TODAY(),"-") -> -97 | L13: 46303 | M13: =IF(ISNUMBER(L13),L13-TODAY(),"-") -> 42 | N13: - | O13: =IF(ISNUMBER(N13),N13-TODAY(),"-") -> - | P13: عطل ميكانيكي - مشكلة في المحرك
A14: 12 | B14: معطلة | C14: ب أ ب 6953 | D14: 2015 | E14: بكب غماره | F14: - | G14: - | H14: 169804410 | I14: 7000473079 | J14: 46139 | K14: =IF(ISNUMBER(J14),J14-TODAY(),"-") -> -122 | L14: 46420 | M14: =IF(ISNUMBER(L14),L14-TODAY(),"-") -> 159 | N14: - | O14: =IF(ISNUMBER(N14),N14-TODAY(),"-") -> - | P14: عطل ميكانيكي - مشكلة في المحرك
A15: 13 | B15: معطلة | C15: ب ح ل 4434 | D15: 2020 | E15: تي 60 بيك اب | F15: - | G15: - | H15: 308047710 | I15: 7000473079 | J15: 46133 | K15: =IF(ISNUMBER(J15),J15-TODAY(),"-") -> -128 | L15: 47098 | M15: =IF(ISNUMBER(L15),L15-TODAY(),"-") -> 837 | N15: - | O15: =IF(ISNUMBER(N15),N15-TODAY(),"-") -> - | P15: عطل ميكانيكي - مشكلة في المحرك
A16: 14 | B16: اسبير | C16: ب ص ب 5129 | D16: 2022 | E16: فان | F16: - | G16: - | H16: 58440910 | I16: 7000473079 | J16: 46416 | K16: =IF(ISNUMBER(J16),J16-TODAY(),"-") -> 155 | L16: 46790 | M16: =IF(ISNUMBER(L16),L16-TODAY(),"-") -> 529 | N16: - | O16: =IF(ISNUMBER(N16),N16-TODAY(),"-") -> - | P16: صالحة
A17: 15 | B17: معطلة | C17: ب س ل 5541 | D17: 2022 | E17: غمارتين | F17: - | G17: - | H17: 129726810 | I17: 7000473079 | J17: 46164 | K17: =IF(ISNUMBER(J17),J17-TODAY(),"-") -> -97 | L17: 46571 | M17: =IF(ISNUMBER(L17),L17-TODAY(),"-") -> 310 | N17: - | O17: =IF(ISNUMBER(N17),N17-TODAY(),"-") -> - | P17: الهولز الهواء - تم طلب القطع
A18: 16 | B18: معطلة | C18: ب ح ه 5088 | D18: 2016 | E18: بكب غماره | F18: - | G18: - | H18: 487059510 | I18: 7000473079 | J18: 46284 | K18: =IF(ISNUMBER(J18),J18-TODAY(),"-") -> 23 | L18: 47094 | M18: =IF(ISNUMBER(L18),L18-TODAY(),"-") -> 833 | N18: - | O18: =IF(ISNUMBER(N18),N18-TODAY(),"-") -> - | P18: تهريب زيت المكينة
A19: 17 | B19: معطلة | C19: رقم 1 | D19: 2012 | E19: فوركلفت تويوتا | F19: - | G19: - | H19: - | I19: - | J19: - | K19: - | L19: - | M19: - | N19: - | O19: =IF(ISNUMBER(N19),N19-TODAY(),"-") -> - | P19: عطل في الحذاف وكراسي المكينه وقير طرنبه ديزل

Sheet السائقون في إجازة
A1: السائقون في إجازة
A3: م | B3: الرقم الوظيفي | C3: اسم السائق | D3: رقم الإقامة | E3: الوظيفة | F3: تاريخ انتهاء بطاقة السائق | G3: الأيام المتبقية | H3: رقم الجوال | I3: الملاحظات
A4: 1 | B4: 100321 | C4: سراج ثاندو عبدول | D4: 2192810774 | E4: موزع | F4: منتهي | G4: =IF(ISNUMBER(F4),F4-TODAY(),"-") -> - | H4: 533858352 | I4: متغيب عن العمل
A5: 2 | B5: 101225 | C5: نديم فضل سبحان | D5: 2472649249 | E5: موزع | F5: 46515 | G5: =IF(ISNUMBER(F5),F5-TODAY(),"-") -> 254 | H5: 501901731 | I5: لا يوجد
A6: 3 | B6: 100385 | C6: رفيق اسان بيلات | D6: 2407663372 | E6: موصل | F6: 46515 | G6: =IF(ISNUMBER(F6),F6-TODAY(),"-") -> 254 | H6: 570528945 | I6: لا يوجد
A7: 4 | B7: 101238 | C7: علاء عبد النبي رفاعي احمد | D7: 2485516401 | E7: موزع | F7: 46515 | G7: =IF(ISNUMBER(F7),F7-TODAY(),"-") -> 254 | H7: 535690637 | I7: لا يوجد
A8: 5 | B8: 101199 | C8: محمد عبدالنبي رفاعي احمد | D8: 2468851676 | E8: موزع | F8: 46330 | G8: =IF(ISNUMBER(F8),F8-TODAY(),"-") -> 69 | H8: 558654476 | I8: لا يوجد

Sheet بيانات_الربط
A2: ='سجل النقل'!C5 -> شمون مياه ادريس مياه | B2: ='سجل النقل'!F5 -> ا س م 8013 | C2: الفحص الدوري | D2: ='سجل النقل'!L5 -> 46478 | E2: ='سجل النقل'!M5 -> 217 | F2: =IF(ISNUMBER(E2),E2+ROW()/100000,"") -> 217.00002
A3: ='سجل النقل'!C6 -> مد سيف | B3: ='سجل النقل'!F6 -> أ س م 8025 | C3: الفحص الدوري | D3: ='سجل النقل'!L6 -> 46309 | E3: ='سجل النقل'!M6 -> 48 | F3: =IF(ISNUMBER(E3),E3+ROW()/100000,"") -> 48.00003
A4: ='سجل النقل'!C7 -> محمد عبدالصبور عبدالعزيز | B4: ='سجل النقل'!F7 -> ا س م 8024 | C4: الفحص الدوري | D4: ='سجل النقل'!L7 -> 46309 | E4: ='سجل النقل'!M7 -> 48 | F4: =IF(ISNUMBER(E4),E4+ROW()/100000,"") -> 48.00004
A5: ='سجل النقل'!C8 -> كابيل مياه | B5: ='سجل النقل'!F8 -> ا س ح 8714 | C5: الفحص الدوري | D5: ='سجل النقل'!L8 -> 46295 | E5: ='سجل النقل'!M8 -> 34 | F5: =IF(ISNUMBER(E5),E5+ROW()/100000,"") -> 34.00005
A6: ='سجل النقل'!C9 -> تنفير حسين | B6: ='سجل النقل'!F9 -> ا ر ع 2234 | C6: الفحص الدوري | D6: ='سجل النقل'!L9 -> 46563 | E6: ='سجل النقل'!M9 -> 302 | F6: =IF(ISNUMBER(E6),E6+ROW()/100000,"") -> 302.00006
A7: ='سجل النقل'!C10 -> محمد مصلح حمادي محسن | B7: ='سجل النقل'!F10 -> ا ر و 4140 | C7: الفحص الدوري | D7: ='سجل النقل'!L10 -> 46475 | E7: ='سجل النقل'!M10 -> 214 | F7: =IF(ISNUMBER(E7),E7+ROW()/100000,"") -> 214.00007
A8: ='سجل النقل'!C11 -> مارييل فينود | B8: ='سجل النقل'!F11 -> ا س 8015 | C8: الفحص الدوري | D8: ='سجل النقل'!L11 -> 46536 | E8: ='سجل النقل'!M11 -> 275 | F8: =IF(ISNUMBER(E8),E8+ROW()/100000,"") -> 275.00008
A9: ='سجل النقل'!C12 -> محمد يونس | B9: ='سجل النقل'!F12 -> ا س ق 7776 | C9: الفحص الدوري | D9: ='سجل النقل'!L12 -> 46384 | E9: ='سجل النقل'!M12 -> 123 | F9: =IF(ISNUMBER(E9),E9+ROW()/100000,"") -> 123.00009
A10: ='سجل النقل'!C13 -> ابراهيم محمد ابوزيد محمد | B10: ='سجل النقل'!F13 -> ا ر ع 2232 | C10: الفحص الدوري | D10: ='سجل النقل'!L13 -> 46521 | E10: ='سجل النقل'!M13 -> 260 | F10: =IF(ISNUMBER(E10),E10+ROW()/100000,"") -> 260.0001
A11: ='سجل النقل'!C14 -> انفير كاريماري عمير | B11: ='سجل النقل'!F14 -> أ س ر 8873 | C11: الفحص الدوري | D11: ='سجل النقل'!L14 -> 46296 | E11: ='سجل النقل'!M14 -> 35 | F11: =IF(ISNUMBER(E11),E11+ROW()/100000,"") -> 35.00011
A12: ='سجل النقل'!C15 -> ارجوان | B12: ='سجل النقل'!F15 -> ا س م 8033 | C12: الفحص الدوري | D12: ='سجل النقل'!L15 -> 46478 | E12: ='سجل النقل'!M15 -> 217 | F12: =IF(ISNUMBER(E12),E12+ROW()/100000,"") -> 217.00012
A13: ='سجل النقل'!C16 -> اجيت راجا | B13: ='سجل النقل'!F16 -> ا ر و 4084 | C13: الفحص الدوري | D13: ='سجل النقل'!L16 -> 46384 | E13: ='سجل النقل'!M16 -> 123 | F13: =IF(ISNUMBER(E13),E13+ROW()/100000,"") -> 123.00013
... A27: ='سجل النقل'!C30 -> شوكت علي | B27: ='سجل النقل'!F30 -> ا س ق 7920 | C27: الفحص الدوري | D27: ='سجل النقل'!L30 -> 46641 | E27: ='سجل النقل'!M30 -> 380 | F27: =IF(ISNUMBER(E27),E27+ROW()/100000,"") -> 380.00027
A28: ="" | B28: ="" | C28: الفحص الدوري | D28: ="" | E28: ="" | F28: =IF(ISNUMBER(E28),E28+ROW()/100000,"")
A29: ='سجل النقل'!C31 -> انال كومار | B29: ='سجل النقل'!F31 -> ا س ح 8715 | C29: الفحص الدوري | D29: ='سجل النقل'!L31 -> 46433 | E29: ='سجل النقل'!M31 -> 172 | F29: =IF(ISNUMBER(E29),E29+ROW()/100000,"") -> 172.00029
A30: ='سجل النقل'!C32 -> احمد دنقل | B30: ='سجل النقل'!F32 -> ا ص ا 7810 | C30: الفحص الدوري | D30: ='سجل النقل'!L32 -> 46623 | E30: ='سجل النقل'!M32 -> 362 | F30: =IF(ISNUMBER(E30),E30+ROW()/100000,"") -> 362.0003
A31: ='سجل النقل'!C33 -> محمد عبدالرحمن السيد المندوه | B31: ='سجل النقل'!F33 -> أ ص ق 6855 | C31: الفحص الدوري | D31: ='سجل النقل'!L33 -> 46478 | E31: ='سجل النقل'!M33 -> 217 | F31: =IF(ISNUMBER(E31),E31+ROW()/100000,"") -> 217.00031
A32: ='سجل النقل'!C5 -> شمون مياه ادريس مياه | B32: ='سجل النقل'!F5 -> ا س م 8013 | C32: رخصة السير | D32: ='سجل النقل'!N5 -> 46397 | E32: ='سجل النقل'!O5 -> 136 | F32: =IF(ISNUMBER(E32),E32+ROW()/100000,"") -> 136.00032
A33: ='سجل النقل'!C6 -> مد سيف | B33: ='سجل النقل'!F6 -> أ س م 8025 | C33: رخصة السير | D33: ='سجل النقل'!N6 -> 46398 | E33: ='سجل النقل'!O6 -> 137 | F33: =IF(ISNUMBER(E33),E33+ROW()/100000,"") -> 137.00033
A34: ='سجل النقل'!C7 -> محمد عبدالصبور عبدالعزيز | B34: ='سجل النقل'!F7 -> ا س م 8024 | C34: رخصة السير | D34: ='سجل النقل'!N7 -> 46398 | E34: ='سجل النقل'!O7 -> 137 | F34: =IF(ISNUMBER(E34),E34+ROW()/100000,"") -> 137.00034
A35: ='سجل النقل'!C8 -> كابيل مياه | B35: ='سجل النقل'!F8 -> ا س ح 8714 | C35: رخصة السير | D35: ='سجل النقل'!N8 -> 47192 | E35: ='سجل النقل'!O8 -> 931 | F35: =IF(ISNUMBER(E35),E35+ROW()/100000,"") -> 931.00035
A36: ='سجل النقل'!C9 -> تنفير حسين | B36: ='سجل النقل'!F9 -> ا ر ع 2234 | C36: رخصة السير | D36: ='سجل النقل'!N9 -> 46272 | E36: ='سجل النقل'!O9 -> 11 | F36: =IF(ISNUMBER(E36),E36+ROW()/100000,"") -> 11.00036
A37: ='سجل النقل'!C10 -> محمد مصلح حمادي محسن | B37: ='سجل النقل'!F10 -> ا ر و 4140 | C37: رخصة السير | D37: ='سجل النقل'!N10 -> 46997 | E37: ='سجل النقل'!O10 -> 736 | F37: =IF(ISNUMBER(E37),E37+ROW()/100000,"") -> 736.00037
A38: ='سجل النقل'!C11 -> مارييل فينود | B38: ='سجل النقل'!F11 -> ا س 8015 | C38: رخصة السير | D38: ='سجل النقل'!N11 -> 46398 | E38: ='سجل النقل'!O11 -> 137 | F38: =IF(ISNUMBER(E38),E38+ROW()/100000,"") -> 137.00038
A39: ='سجل النقل'!C12 -> محمد يونس | B39: ='سجل النقل'!F12 -> ا س ق 7776 | C39: رخصة السير | D39: ='سجل النقل'!N12 -> 46282 | E39: ='سجل النقل'!O12 -> 21 | F39: =IF(ISNUMBER(E39),E39+ROW()/100000,"") -> 21.00039
A40: ='سجل النقل'!C13 -> ابراهيم محمد ابوزيد محمد | B40: ='سجل النقل'!F13 -> ا ر ع 2232 | C40: رخصة السير | D40: ='سجل النقل'!N13 -> 46265 | E40: ='سجل النقل'!O13 -> 4 | F40: =IF(ISNUMBER(E40),E40+ROW()/100000,"") -> 4.0004
A41: ='سجل النقل'!C14 -> انفير كاريماري عمير | B41: ='سجل النقل'!F14 -> أ س ر 8873 | C41: رخصة السير | D41: ='سجل النقل'!N14 -> 46221 | E41: ='سجل النقل'!O14 -> -40 | F41: =IF(ISNUMBER(E41),E41+ROW()/100000,"") -> -39.99959
A42: ='سجل النقل'!C15 -> ارجوان | B42: ='سجل النقل'!F15 -> ا س م 8033 | C42: رخصة السير | D42: ='سجل النقل'!N15 -> 46398 | E42: ='سجل النقل'!O15 -> 137 | F42: =IF(ISNUMBER(E42),E42+ROW()/100000,"") -> 137.00042
A43: ='سجل النقل'!C16 -> اجيت راجا | B43: ='سجل النقل'!F16 -> ا ر و 4084 | C43: رخصة السير | D43: ='سجل النقل'!N16 -> 46858 | E43: ='سجل النقل'!O16 -> 597 | F43: =IF(ISNUMBER(E43),E43+ROW()/100000,"") -> 597.00043
... A57: ='سجل النقل'!C30 -> شوكت علي | B57: ='سجل النقل'!F30 -> ا س ق 7920 | C57: رخصة السير | D57: ='سجل النقل'!N30 -> 46275 | E57: ='سجل النقل'!O30 -> 14 | F57: =IF(ISNUMBER(E57),E57+ROW()/100000,"") -> 14.00057
A58: ="" | B58: ="" | C58: رخصة السير | D58: ="" | E58: ="" | F58: =IF(ISNUMBER(E58),E58+ROW()/100000,"")
A59: ='سجل النقل'!C31 -> انال كومار | B59: ='سجل النقل'!F31 -> ا س ح 8715 | C59: رخصة السير | D59: ='سجل النقل'!N31 -> 47210 | E59: ='سجل النقل'!O31 -> 949 | F59: =IF(ISNUMBER(E59),E59+ROW()/100000,"") -> 949.00059
A60: ='سجل النقل'!C32 -> احمد دنقل | B60: ='سجل النقل'!F32 -> ا ص ا 7810 | C60: رخصة السير | D60: ='سجل النقل'!N32 -> 46499 | E60: ='سجل النقل'!O32 -> 238 | F60: =IF(ISNUMBER(E60),E60+ROW()/100000,"") -> 238.0006
A61: ='سجل النقل'!C33 -> محمد عبدالرحمن السيد المندوه | B61: ='سجل النقل'!F33 -> أ ص ق 6855 | C61: رخصة السير | D61: ='سجل النقل'!N33 -> 46592 | E61: ='سجل النقل'!O33 -> 331 | F61: =IF(ISNUMBER(E61),E61+ROW()/100000,"") -> 331.00061
A62: ='سجل النقل'!C5 -> شمون مياه ادريس مياه | B62: ='سجل النقل'!F5 -> ا س م 8013 | C62: بطاقة السائق | D62: ='سجل النقل'!P5 -> 46515 | E62: ='سجل النقل'!Q5 -> 254 | F62: =IF(ISNUMBER(E62),E62+ROW()/100000,"") -> 254.00062
A63: ='سجل النقل'!C6 -> مد سيف | B63: ='سجل النقل'!F6 -> أ س م 8025 | C63: بطاقة السائق | D63: ='سجل النقل'!P6 -> 46515 | E63: ='سجل النقل'!Q6 -> 254 | F63: =IF(ISNUMBER(E63),E63+ROW()/100000,"") -> 254.00063
A64: ='سجل النقل'!C7 -> محمد عبدالصبور عبدالعزيز | B64: ='سجل النقل'!F7 -> ا س م 8024 | C64: بطاقة السائق | D64: ='سجل النقل'!P7 -> 46515 | E64: ='سجل النقل'!Q7 -> 254 | F64: =IF(ISNUMBER(E64),E64+ROW()/100000,"") -> 254.00064
A65: ='سجل النقل'!C8 -> كابيل مياه | B65: ='سجل النقل'!F8 -> ا س ح 8714 | C65: بطاقة السائق | D65: ='سجل النقل'!P8 -> 46198 | E65: ='سجل النقل'!Q8 -> -63 | F65: =IF(ISNUMBER(E65),E65+ROW()/100000,"") -> -62.99935
A66: ='سجل النقل'!C9 -> تنفير حسين | B66: ='سجل النقل'!F9 -> ا ر ع 2234 | C66: بطاقة السائق | D66: ='سجل النقل'!P9 -> 46515 | E66: ='سجل النقل'!Q9 -> 254 | F66: =IF(ISNUMBER(E66),E66+ROW()/100000,"") -> 254.00066
A67: ='سجل النقل'!C10 -> محمد مصلح حمادي محسن | B67: ='سجل النقل'!F10 -> ا ر و 4140 | C67: بطاقة السائق | D67: ='سجل النقل'!P10 -> 46505 | E67: ='سجل النقل'!Q10 -> 244 | F67: =IF(ISNUMBER(E67),E67+ROW()/100000,"") -> 244.00067
...
