Workbook

Sheet لوحة المعلومات
A1: لوحة معلومات أسطول المركبات - فرع الدمام
A2: تاريخ آخر تحديث: | B2: 46194 | D2: تاريخ اليوم: | E2: =TODAY() -> 46216
A4: إجمالي عدد السائقين | C4: عدد الموصلين | E4: عدد الموزعين | G4: سائقون في إجازة | I4: مركبات أسبير/معطلة
A5: =COUNTA('المركبات النشطة'!B5:B34) -> 30 | C5: =COUNTIF('المركبات النشطة'!E5:E34,"موصل") -> 16 | E5: =COUNTIF('المركبات النشطة'!E5:E34,"موزع") -> 14 | G5: =COUNTA('السائقون في إجازة'!B4:B6) -> 3 | I5: =COUNTA('الأسبير والمعطلة'!A4:A9) -> 6
A7: ⚠ المستندات التي تنتهي خلال 30 يومًا أو منتهية
A8: م | B8: الاسم | C8: رقم اللوحة | D8: نوع المستند | E8: تاريخ الانتهاء | F8: الأيام المتبقية
A9: =IF($G9="","",1) -> 1 | B9: =IF($G9="","",INDEX(بيانات_الربط!$A$2:$A$121,MATCH($G9,بيانات_الربط!$F$2:$F$121,0))) -> كابيل مياه | C9: =IF($G9="","",INDEX(بيانات_الربط!$B$2:$B$121,MATCH($G9,بيانات_الربط!$F$2:$F$121,0))) -> ا س ح 8714 | D9: =IF($G9="","",INDEX(بيانات_الربط!$C$2:$C$121,MATCH($G9,بيانات_الربط!$F$2:$F$121,0))) -> بطاقة السائق | E9: =IF($G9="","",INDEX(بيانات_الربط!$D$2:$D$121,MATCH($G9,بيانات_الربط!$F$2:$F$121,0))) -> 46198 | F9: =IF($G9="","",INDEX(بيانات_الربط!$E$2:$E$121,MATCH($G9,بيانات_الربط!$F$2:$F$121,0))) -> -18 | G9: =IFERROR(SMALL(بيانات_الربط!$F$2:$F$121,1),"") -> -17.99935
A10: =IF($G10="","",2) -> 2 | B10: =IF($G10="","",INDEX(بيانات_الربط!$A$2:$A$121,MATCH($G10,بيانات_الربط!$F$2:$F$121,0))) -> ابراهيم محمد ابوزيد محمد | C10: =IF($G10="","",INDEX(بيانات_الربط!$B$2:$B$121,MATCH($G10,بيانات_الربط!$F$2:$F$121,0))) -> أ ر ع 2233 | D10: =IF($G10="","",INDEX(بيانات_الربط!$C$2:$C$121,MATCH($G10,بيانات_الربط!$F$2:$F$121,0))) -> الفحص الدوري | E10: =IF($G10="","",INDEX(بيانات_الربط!$D$2:$D$121,MATCH($G10,بيانات_الربط!$F$2:$F$121,0))) -> 46213 | F10: =IF($G10="","",INDEX(بيانات_الربط!$E$2:$E$121,MATCH($G10,بيانات_الربط!$F$2:$F$121,0))) -> -3 | G10: =IFERROR(SMALL(بيانات_الربط!$F$2:$F$121,2),"") -> -2.9999
A11: =IF($G11="","",3) -> 3 | B11: =IF($G11="","",INDEX(بيانات_الربط!$A$2:$A$121,MATCH($G11,بيانات_الربط!$F$2:$F$121,0))) -> شوكت علي | C11: =IF($G11="","",INDEX(بيانات_الربط!$B$2:$B$121,MATCH($G11,بيانات_الربط!$F$2:$F$121,0))) -> أ س ر 8873 | D11: =IF($G11="","",INDEX(بيانات_الربط!$C$2:$C$121,MATCH($G11,بيانات_الربط!$F$2:$F$121,0))) -> رخصة السير | E11: =IF($G11="","",INDEX(بيانات_الربط!$D$2:$D$121,MATCH($G11,بيانات_الربط!$F$2:$F$121,0))) -> 46241 | F11: =IF($G11="","",INDEX(بيانات_الربط!$E$2:$E$121,MATCH($G11,بيانات_الربط!$F$2:$F$121,0))) -> 25 | G11: =IFERROR(SMALL(بيانات_الربط!$F$2:$F$121,3),"") -> 25.00057
A12: =IF($G12="","",4) -> 4 | B12: =IF($G12="","",INDEX(بيانات_الربط!$A$2:$A$121,MATCH($G12,بيانات_الربط!$F$2:$F$121,0))) -> احمد دنقل | C12: =IF($G12="","",INDEX(بيانات_الربط!$B$2:$B$121,MATCH($G12,بيانات_الربط!$F$2:$F$121,0))) -> ا ص ا 7810 | D12: =IF($G12="","",INDEX(بيانات_الربط!$C$2:$C$121,MATCH($G12,بيانات_الربط!$F$2:$F$121,0))) -> الفحص الدوري | E12: =IF($G12="","",INDEX(بيانات_الربط!$D$2:$D$121,MATCH($G12,بيانات_الربط!$F$2:$F$121,0))) -> 46258 | F12: =IF($G12="","",INDEX(بيانات_الربط!$E$2:$E$121,MATCH($G12,بيانات_الربط!$F$2:$F$121,0))) -> 42 | G12: =IFERROR(SMALL(بيانات_الربط!$F$2:$F$121,4),"") -> 42.0003
A13: =IF($G13="","",5) -> 5 | B13: =IF($G13="","",INDEX(بيانات_الربط!$A$2:$A$121,MATCH($G13,بيانات_الربط!$F$2:$F$121,0))) -> تنفير حسين | C13: =IF($G13="","",INDEX(بيانات_الربط!$B$2:$B$121,MATCH($G13,بيانات_الربط!$F$2:$F$121,0))) -> ا ر ع 2234 | D13: =IF($G13="","",INDEX(بيانات_الربط!$C$2:$C$121,MATCH($G13,بيانات_الربط!$F$2:$F$121,0))) -> رخصة السير | E13: =IF($G13="","",INDEX(بيانات_الربط!$D$2:$D$121,MATCH($G13,بيانات_الربط!$F$2:$F$121,0))) -> 46272 | F13: =IF($G13="","",INDEX(بيانات_الربط!$E$2:$E$121,MATCH($G13,بيانات_الربط!$F$2:$F$121,0))) -> 56 | G13: =IFERROR(SMALL(بيانات_الربط!$F$2:$F$121,5),"") -> 56.00036
A14: =IF($G14="","",6) -> 6 | B14: =IF($G14="","",INDEX(بيانات_الربط!$A$2:$A$121,MATCH($G14,بيانات_الربط!$F$2:$F$121,0))) -> ابراهيم محمد ابوزيد محمد | C14: =IF($G14="","",INDEX(بيانات_الربط!$B$2:$B$121,MATCH($G14,بيانات_الربط!$F$2:$F$121,0))) -> أ ر ع 2233 | D14: =IF($G14="","",INDEX(بيانات_الربط!$C$2:$C$121,MATCH($G14,بيانات_الربط!$F$2:$F$121,0))) -> رخصة السير | E14: =IF($G14="","",INDEX(بيانات_الربط!$D$2:$D$121,MATCH($G14,بيانات_الربط!$F$2:$F$121,0))) -> 46272 | F14: =IF($G14="","",INDEX(بيانات_الربط!$E$2:$E$121,MATCH($G14,بيانات_الربط!$F$2:$F$121,0))) -> 56 | G14: =IFERROR(SMALL(بيانات_الربط!$F$2:$F$121,6),"") -> 56.0004
A15: =IF($G15="","",7) -> 7 | B15: =IF($G15="","",INDEX(بيانات_الربط!$A$2:$A$121,MATCH($G15,بيانات_الربط!$F$2:$F$121,0))) -> مد سيف الاسلام | C15: =IF($G15="","",INDEX(بيانات_الربط!$B$2:$B$121,MATCH($G15,بيانات_الربط!$F$2:$F$121,0))) -> ا ر ع 2240 | D15: =IF($G15="","",INDEX(بيانات_الربط!$C$2:$C$121,MATCH($G15,بيانات_الربط!$F$2:$F$121,0))) -> رخصة السير | E15: =IF($G15="","",INDEX(بيانات_الربط!$D$2:$D$121,MATCH($G15,بيانات_الربط!$F$2:$F$121,0))) -> 46272 | F15: =IF($G15="","",INDEX(بيانات_الربط!$E$2:$E$121,MATCH($G15,بيانات_الربط!$F$2:$F$121,0))) -> 56 | G15: =IFERROR(SMALL(بيانات_الربط!$F$2:$F$121,7),"") -> 56.00056
A19: موصل | B19: =COUNTIF('المركبات النشطة'!E5:E34,"موصل") -> 16
A20: موزع | B20: =COUNTIF('المركبات النشطة'!E5:E34,"موزع") -> 14
A21: ايسوزو دينا | B21: =COUNTIF('المركبات النشطة'!H5:H34,"ايسوزو دينا") -> 6
A22: ايسوزو لوري | B22: =COUNTIF('المركبات النشطة'!H5:H34,"ايسوزو لوري") -> 13
A23: متسوبيشي دينا | B23: =COUNTIF('المركبات النشطة'!H5:H34,"متسوبيشي دينا") -> 8
A24: متسوبيشي لوري | B24: =COUNTIF('المركبات النشطة'!H5:H34,"متسوبيشي لوري") -> 2
A25: هينو دينا | B25: =COUNTIF('المركبات النشطة'!H5:H34,"هينو دينا") -> 1
A27: اعداد / ادارة قسم الحركة

Sheet المركبات النشطة
A1: جدول تحديث المركبات والسائقين الأسبوعي - فرع الدمام 2026
A2: تاريخ آخر تحديث: | T2: =TODAY() -> 46216 | U2: تاريخ اليوم:
A4: م | B4: الرقم الوظيفي | C4: اسم السائق | D4: رقم الإقامة | E4: الوظيفة | F4: رقم اللوحة | G4: الموديل | H4: نوع المركبة | I4: عدد الطبالي | J4: الحمولة | K4: الرقم التسلسلي | L4: تاريخ انتهاء الفحص الدوري | M4: الأيام المتبقية | N4: تاريخ انتهاء رخصة السير | O4: الأيام المتبقية | P4: تاريخ انتهاء بطاقة السائق | Q4: الأيام المتبقية | R4: تاريخ انتهاء بطاقة التشغيل | S4: الأيام المتبقية | T4: الملاحظات | U4: رقم الجوال
A5: 1 | B5: 100310 | C5: شمون مياه ادريس مياه | D5: 2253252916 | E5: موصل | F5: ا س م 8013 | G5: 2023 | H5: ايسوزو لوري | I5: 8 | J5: 3 | K5: 17554020 | L5: 46478 | M5: =IF(ISNUMBER(L5),L5-TODAY(),"-") -> 262 | N5: 46397 | O5: =IF(ISNUMBER(N5),N5-TODAY(),"-") -> 181 | P5: 46515 | Q5: =IF(ISNUMBER(P5),P5-TODAY(),"-") -> 299 | R5: 46479 | S5: =IF(ISNUMBER(R5),R5-TODAY(),"-") -> 263 | T5: لا يوجد | U5: 504125217
A6: 2 | B6: 100217 | C6: مارييل فينود | D6: 2501620039 | E6: موصل | F6: أ س م 8025 | G6: 2023 | H6: ايسوزو لوري | I6: 8 | J6: 3 | K6: 968754020 | L6: 46309 | M6: =IF(ISNUMBER(L6),L6-TODAY(),"-") -> 93 | N6: 46398 | O6: =IF(ISNUMBER(N6),N6-TODAY(),"-") -> 182 | P6: 46534 | Q6: =IF(ISNUMBER(P6),P6-TODAY(),"-") -> 318 | R6: 46484 | S6: =IF(ISNUMBER(R6),R6-TODAY(),"-") -> 268 | T6: لايوجد بطاقة سائق | U6: 564915114
A7: 3 | B7: 100327 | C7: محمد عبدالصبور عبدالعزيز | D7: 2283628259 | E7: موصل | F7: ا س م 8024 | G7: 2023 | H7: ايسوزو لوري | I7: 8 | J7: 3 | K7: 358754020 | L7: 46309 | M7: =IF(ISNUMBER(L7),L7-TODAY(),"-") -> 93 | N7: 46398 | O7: =IF(ISNUMBER(N7),N7-TODAY(),"-") -> 182 | P7: 46515 | Q7: =IF(ISNUMBER(P7),P7-TODAY(),"-") -> 299 | R7: 46505 | S7: =IF(ISNUMBER(R7),R7-TODAY(),"-") -> 289 | T7: لا يوجد | U7: 565369080
A8: 4 | B8: 100245 | C8: كابيل مياه | D8: 2121612820 | E8: موزع | F8: ا س ح 8714 | G8: 2023 | H8: متسوبيشي دينا | I8: 4 | J8: 3 | K8: 29819910 | L8: 46295 | M8: =IF(ISNUMBER(L8),L8-TODAY(),"-") -> 79 | N8: 47192 | O8: =IF(ISNUMBER(N8),N8-TODAY(),"-") -> 976 | P8: 46198 | Q8: =IF(ISNUMBER(P8),P8-TODAY(),"-") -> -18 | R8: 46515 | S8: =IF(ISNUMBER(R8),R8-TODAY(),"-") -> 299 | T8: (بطاقة مقيدة - تعديل مهنة ) | U8: 567116916
A9: 5 | B9: 102179 | C9: تنفير حسين | D9: 2519784710 | E9: موصل | F9: ا ر ع 2234 | G9: 2020 | H9: متسوبيشي دينا | I9: 4 | J9: 3 | K9: 196860810 | L9: 46563 | M9: =IF(ISNUMBER(L9),L9-TODAY(),"-") -> 347 | N9: 46272 | O9: =IF(ISNUMBER(N9),N9-TODAY(),"-") -> 56 | P9: 46515 | Q9: =IF(ISNUMBER(P9),P9-TODAY(),"-") -> 299 | R9: 46515 | S9: =IF(ISNUMBER(R9),R9-TODAY(),"-") -> 299 | T9: لايوجد | U9: 594535961
A10: 6 | B10: 102181 | C10: محمد مصلح حمادي محسن | D10: 2536883693 | E10: موزع | F10: ا ر و 4140 | G10: 2023 | H10: ايسوزو لوري | I10: 8 | J10: 3 | K10: 826065910 | L10: 46475 | M10: =IF(ISNUMBER(L10),L10-TODAY(),"-") -> 259 | N10: 46997 | O10: =IF(ISNUMBER(N10),N10-TODAY(),"-") -> 781 | P10: 46505 | Q10: =IF(ISNUMBER(P10),P10-TODAY(),"-") -> 289 | R10: 46515 | S10: =IF(ISNUMBER(R10),R10-TODAY(),"-") -> 299 | T10: لايوجد | U10: 548827398
A11: 7 | B11: 101238 | C11: علاء عبد النبي رفاعي احمد | D11: 2485516401 | E11: موزع | F11: ا س 8015 | G11: 2023 | H11: ايسوزو لوري | I11: 8 | J11: 2 | K11: 698454020 | L11: 46536 | M11: =IF(ISNUMBER(L11),L11-TODAY(),"-") -> 320 | N11: 46398 | O11: =IF(ISNUMBER(N11),N11-TODAY(),"-") -> 182 | P11: 46515 | Q11: =IF(ISNUMBER(P11),P11-TODAY(),"-") -> 299 | R11: 46485 | S11: =IF(ISNUMBER(R11),R11-TODAY(),"-") -> 269 | T11: لايوجد | U11: 535690637
A12: 8 | B12: 100385 | C12: رفيق اسان بيلات | D12: 2407663372 | E12: موصل | F12: ا س ق 7776 | G12: 2016 | H12: متسوبيشي لوري | I12: 8 | J12: 2 | K12: 831809610 | L12: 46384 | M12: =IF(ISNUMBER(L12),L12-TODAY(),"-") -> 168 | N12: 46282 | O12: =IF(ISNUMBER(N12),N12-TODAY(),"-") -> 66 | P12: 46515 | Q12: =IF(ISNUMBER(P12),P12-TODAY(),"-") -> 299 | R12: 46515 | S12: =IF(ISNUMBER(R12),R12-TODAY(),"-") -> 299 | T12: لايوجد | U12: 570528945
A13: 9 | B13: 100360 | C13: ابراهيم محمد ابوزيد محمد | D13: 2393652496 | E13: موزع | F13: أ ر ع 2233 | G13: 2023 | H13: متسوبيشي دينا | I13: 4 | J13: 3 | K13: 886860810 | L13: 46213 | M13: =IF(ISNUMBER(L13),L13-TODAY(),"-") -> -3 | N13: 46272 | O13: =IF(ISNUMBER(N13),N13-TODAY(),"-") -> 56 | P13: 46515 | Q13: =IF(ISNUMBER(P13),P13-TODAY(),"-") -> 299 | R13: 46515 | S13: =IF(ISNUMBER(R13),R13-TODAY(),"-") -> 299 | T13: (تعديل مهنة ) | U13: 541364538
A14: 10 | B14: 100332 | C14: انفير كاريماري عمير | D14: 2350147415 | E14: موزع | F14: ا ر و 4085 | G14: 2022 | H14: ايسوزو دينا | I14: 4 | J14: 3 | K14: 211941910 | L14: 46446 | M14: =IF(ISNUMBER(L14),L14-TODAY(),"-") -> 230 | N14: 46858 | O14: =IF(ISNUMBER(N14),N14-TODAY(),"-") -> 642 | P14: 46283 | Q14: =IF(ISNUMBER(P14),P14-TODAY(),"-") -> 67 | R14: 46379 | S14: =IF(ISNUMBER(R14),R14-TODAY(),"-") -> 163 | T14: لايوجد | U14: 571991926
A15: 11 | B15: 102126 | C15: ارجوان | D15: 2530207360 | E15: موزع | F15: ا س م 8033 | G15: 2023 | H15: ايسوزو لوري | I15: 8 | J15: 3 | K15: 207954020 | L15: 46478 | M15: =IF(ISNUMBER(L15),L15-TODAY(),"-") -> 262 | N15: 46398 | O15: =IF(ISNUMBER(N15),N15-TODAY(),"-") -> 182 | P15: 46515 | Q15: =IF(ISNUMBER(P15),P15-TODAY(),"-") -> 299 | R15: 46485 | S15: =IF(ISNUMBER(R15),R15-TODAY(),"-") -> 269 | T15: لا يوجد | U15: 567948210
A16: 12 | B16: 100828 | C16: اجيت راجا | D16: 2461544377 | E16: موزع | F16: ا ر و 4084 | G16: 2022 | H16: ايسوزو دينا | I16: 4 | J16: 3 | K16: 960941910 | L16: 46384 | M16: =IF(ISNUMBER(L16),L16-TODAY(),"-") -> 168 | N16: 46858 | O16: =IF(ISNUMBER(N16),N16-TODAY(),"-") -> 642 | P16: 46388 | Q16: =IF(ISNUMBER(P16),P16-TODAY(),"-") -> 172 | R16: 46379 | S16: =IF(ISNUMBER(R16),R16-TODAY(),"-") -> 163 | T16: لايوجد | U16: 549131428
... A34: 30 | B34: 100574 | C34: محمد عبدالرحمن السيد المندوه | D34: 2441077944 | E34: موزع | F34: أ ص ق 6855 | G34: 2024 | H34: ايسوزو دينا | I34: 4 | J34: 3 | K34: 761431120 | L34: 46478 | M34: =IF(ISNUMBER(L34),L34-TODAY(),"-") -> 262 | N34: 46592 | O34: =IF(ISNUMBER(N34),N34-TODAY(),"-") -> 376 | P34: 46543 | Q34: =IF(ISNUMBER(P34),P34-TODAY(),"-") -> 327 | R34: 46515 | S34: =IF(ISNUMBER(R34),R34-TODAY(),"-") -> 299 | T34: لايوجد | U34: 576559794

Sheet الأسبير والمعطلة
A1: بيان المركبات الأسبير والمعطلة
A3: م | B3: الحالة | C3: رقم اللوحة | D3: الموديل | E3: نوع المركبة | F3: عدد الطبالي | G3: الحمولة | H3: الرقم التسلسلي | I3: تاريخ انتهاء الفحص الدوري | J3: الأيام المتبقية | K3: تاريخ انتهاء رخصة السير | L3: الأيام المتبقية | M3: تاريخ انتهاء بطاقة التشغيل | N3: الأيام المتبقية | O3: الملاحظات
A4: 1 | B4: فحص | C4: ا س ق 7774 | D4: 2016 | E4: متسوبيشي لوري | F4: 8 | G4: 2 | H4: 178838410 | I4: 45978 | J4: =IF(ISNUMBER(I4),I4-TODAY(),"-") -> -238 | K4: 46284 | L4: =IF(ISNUMBER(K4),K4-TODAY(),"-") -> 68 | M4: 46159 | N4: =IF(ISNUMBER(M4),M4-TODAY(),"-") -> -57 | O4: لم يتم تجديد بطاقة التشغيل (فحص دوري- صيانة جهاز التتبع)
A5: 2 | B5: فحص | C5: ا س ق 7821 | D5: 2016 | E5: متسوبيشي لوري | F5: 8 | G5: 3 | H5: 787571510 | I5: 45993 | J5: =IF(ISNUMBER(I5),I5-TODAY(),"-") -> -223 | K5: 46291 | L5: =IF(ISNUMBER(K5),K5-TODAY(),"-") -> 75 | M5: 46159 | N5: =IF(ISNUMBER(M5),M5-TODAY(),"-") -> -57 | O5: لم يتم تجديد بطاقة التشغيل (فحص دوري- صيانة جهاز التتبع)
A6: 3 | B6: اسبير | C6: أ س ق 7775 | D6: 2016 | E6: متسوبيشي لوري | F6: 8 | G6: 2 | H6: 490809610 | I6: 46348 | J6: =IF(ISNUMBER(I6),I6-TODAY(),"-") -> 132 | K6: 46284 | L6: =IF(ISNUMBER(K6),K6-TODAY(),"-") -> 68 | M6: 46159 | N6: =IF(ISNUMBER(M6),M6-TODAY(),"-") -> -57 | O6: تحديد بطاقة التشغيل (صيانة جهاز التتبع)
A7: 4 | B7: معطلة | C7: أ س م 8022 | D7: 2023 | E7: ايسوزو لوري | F7: 8 | G7: 3 | H7: 978754020 | I7: لا يوجد | J7: =IF(ISNUMBER(I7),I7-TODAY(),"-") -> - | K7: 46398 | L7: =IF(ISNUMBER(K7),K7-TODAY(),"-") -> 182 | M7: 46118 | N7: =IF(ISNUMBER(M7),M7-TODAY(),"-") -> -98 | O7: ورشة خارجية لم يتم تجهيزها للتأمين (بطاقة التشغيل منتهية وتحتاج إلى فحص دوري)
A8: 5 | B8: اسبير | C8: ا س ق 7920 | D8: 2016 | E8: متسوبيشي لوري | F8: 8 | G8: 2 | H8: 621809610 | I8: 1447-05-16 | J8: =IF(ISNUMBER(I8),I8-TODAY(),"-") -> - | K8: 46259 | L8: =IF(ISNUMBER(K8),K8-TODAY(),"-") -> 43 | M8: 46515 | N8: =IF(ISNUMBER(M8),M8-TODAY(),"-") -> 299 | O8: عطل في المكيف
A9: 6 | B9: اسبير | C9: ا ر ع 2232 | D9: 2020 | E9: متسوبيشي دينا | F9: 4 | G9: 3 | H9: 386860810 | I9: 46521 | J9: =IF(ISNUMBER(I9),I9-TODAY(),"-") -> 305 | K9: 46275 | L9: =IF(ISNUMBER(K9),K9-TODAY(),"-") -> 59 | M9: 46515 | N9: =IF(ISNUMBER(M9),M9-TODAY(),"-") -> 299 | O9: لا يوجد

Sheet السائقون في إجازة
A1: السائقون في إجازة
A3: م | B3: الرقم الوظيفي | C3: اسم السائق | D3: رقم الإقامة | E3: الوظيفة | F3: تاريخ انتهاء بطاقة السائق | G3: الأيام المتبقية | H3: رقم الجوال | I3: الملاحظات
A4: 1 | B4: 102452 | C4: محمد يونس | D4: 2550977850 | E4: موصل | F4: 46516 | G4: =IF(ISNUMBER(F4),F4-TODAY(),"-") -> 300 | H4: 575806817 | I4: لا يوجد
A5: 2 | B5: 100321 | C5: سراج ثاندو عبدول | D5: 2192810774 | E5: موزع | F5: منتهي | G5: =IF(ISNUMBER(F5),F5-TODAY(),"-") -> - | H5: 533858352 | I5: متغيب عن العمل
A6: 3 | B6: 101225 | C6: نديم فضل سبحان | D6: 2472649249 | E6: موزع | F6: 46515 | G6: =IF(ISNUMBER(F6),F6-TODAY(),"-") -> 299 | H6: 501901731 | I6: لا يوجد

Sheet بيانات_الربط
A2: ='المركبات النشطة'!C5 -> شمون مياه ادريس مياه | B2: ='المركبات النشطة'!F5 -> ا س م 8013 | C2: الفحص الدوري | D2: ='المركبات النشطة'!L5 -> 46478 | E2: ='المركبات النشطة'!M5 -> 262 | F2: =IF(ISNUMBER(E2),E2+ROW()/100000,"") -> 262.00002
A3: ='المركبات النشطة'!C6 -> مارييل فينود | B3: ='المركبات النشطة'!F6 -> أ س م 8025 | C3: الفحص الدوري | D3: ='المركبات النشطة'!L6 -> 46309 | E3: ='المركبات النشطة'!M6 -> 93 | F3: =IF(ISNUMBER(E3),E3+ROW()/100000,"") -> 93.00003
A4: ='المركبات النشطة'!C7 -> محمد عبدالصبور عبدالعزيز | B4: ='المركبات النشطة'!F7 -> ا س م 8024 | C4: الفحص الدوري | D4: ='المركبات النشطة'!L7 -> 46309 | E4: ='المركبات النشطة'!M7 -> 93 | F4: =IF(ISNUMBER(E4),E4+ROW()/100000,"") -> 93.00004
A5: ='المركبات النشطة'!C8 -> كابيل مياه | B5: ='المركبات النشطة'!F8 -> ا س ح 8714 | C5: الفحص الدوري | D5: ='المركبات النشطة'!L8 -> 46295 | E5: ='المركبات النشطة'!M8 -> 79 | F5: =IF(ISNUMBER(E5),E5+ROW()/100000,"") -> 79.00005
A6: ='المركبات النشطة'!C9 -> تنفير حسين | B6: ='المركبات النشطة'!F9 -> ا ر ع 2234 | C6: الفحص الدوري | D6: ='المركبات النشطة'!L9 -> 46563 | E6: ='المركبات النشطة'!M9 -> 347 | F6: =IF(ISNUMBER(E6),E6+ROW()/100000,"") -> 347.00006
A7: ='المركبات النشطة'!C10 -> محمد مصلح حمادي محسن | B7: ='المركبات النشطة'!F10 -> ا ر و 4140 | C7: الفحص الدوري | D7: ='المركبات النشطة'!L10 -> 46475 | E7: ='المركبات النشطة'!M10 -> 259 | F7: =IF(ISNUMBER(E7),E7+ROW()/100000,"") -> 259.00007
A8: ='المركبات النشطة'!C11 -> علاء عبد النبي رفاعي احمد | B8: ='المركبات النشطة'!F11 -> ا س 8015 | C8: الفحص الدوري | D8: ='المركبات النشطة'!L11 -> 46536 | E8: ='المركبات النشطة'!M11 -> 320 | F8: =IF(ISNUMBER(E8),E8+ROW()/100000,"") -> 320.00008
A9: ='المركبات النشطة'!C12 -> رفيق اسان بيلات | B9: ='المركبات النشطة'!F12 -> ا س ق 7776 | C9: الفحص الدوري | D9: ='المركبات النشطة'!L12 -> 46384 | E9: ='المركبات النشطة'!M12 -> 168 | F9: =IF(ISNUMBER(E9),E9+ROW()/100000,"") -> 168.00009
A10: ='المركبات النشطة'!C13 -> ابراهيم محمد ابوزيد محمد | B10: ='المركبات النشطة'!F13 -> أ ر ع 2233 | C10: الفحص الدوري | D10: ='المركبات النشطة'!L13 -> 46213 | E10: ='المركبات النشطة'!M13 -> -3 | F10: =IF(ISNUMBER(E10),E10+ROW()/100000,"") -> -2.9999
A11: ='المركبات النشطة'!C14 -> انفير كاريماري عمير | B11: ='المركبات النشطة'!F14 -> ا ر و 4085 | C11: الفحص الدوري | D11: ='المركبات النشطة'!L14 -> 46446 | E11: ='المركبات النشطة'!M14 -> 230 | F11: =IF(ISNUMBER(E11),E11+ROW()/100000,"") -> 230.00011
A12: ='المركبات النشطة'!C15 -> ارجوان | B12: ='المركبات النشطة'!F15 -> ا س م 8033 | C12: الفحص الدوري | D12: ='المركبات النشطة'!L15 -> 46478 | E12: ='المركبات النشطة'!M15 -> 262 | F12: =IF(ISNUMBER(E12),E12+ROW()/100000,"") -> 262.00012
A13: ='المركبات النشطة'!C16 -> اجيت راجا | B13: ='المركبات النشطة'!F16 -> ا ر و 4084 | C13: الفحص الدوري | D13: ='المركبات النشطة'!L16 -> 46384 | E13: ='المركبات النشطة'!M16 -> 168 | F13: =IF(ISNUMBER(E13),E13+ROW()/100000,"") -> 168.00013
... A31: ='المركبات النشطة'!C34 -> محمد عبدالرحمن السيد المندوه | B31: ='المركبات النشطة'!F34 -> أ ص ق 6855 | C31: الفحص الدوري | D31: ='المركبات النشطة'!L34 -> 46478 | E31: ='المركبات النشطة'!M34 -> 262 | F31: =IF(ISNUMBER(E31),E31+ROW()/100000,"") -> 262.00031
A32: ='المركبات النشطة'!C5 -> شمون مياه ادريس مياه | B32: ='المركبات النشطة'!F5 -> ا س م 8013 | C32: رخصة السير | D32: ='المركبات النشطة'!N5 -> 46397 | E32: ='المركبات النشطة'!O5 -> 181 | F32: =IF(ISNUMBER(E32),E32+ROW()/100000,"") -> 181.00032
A33: ='المركبات النشطة'!C6 -> مارييل فينود | B33: ='المركبات النشطة'!F6 -> أ س م 8025 | C33: رخصة السير | D33: ='المركبات النشطة'!N6 -> 46398 | E33: ='المركبات النشطة'!O6 -> 182 | F33: =IF(ISNUMBER(E33),E33+ROW()/100000,"") -> 182.00033
A34: ='المركبات النشطة'!C7 -> محمد عبدالصبور عبدالعزيز | B34: ='المركبات النشطة'!F7 -> ا س م 8024 | C34: رخصة السير | D34: ='المركبات النشطة'!N7 -> 46398 | E34: ='المركبات النشطة'!O7 -> 182 | F34: =IF(ISNUMBER(E34),E34+ROW()/100000,"") -> 182.00034
A35: ='المركبات النشطة'!C8 -> كابيل مياه | B35: ='المركبات النشطة'!F8 -> ا س ح 8714 | C35: رخصة السير | D35: ='المركبات النشطة'!N8 -> 47192 | E35: ='المركبات النشطة'!O8 -> 976 | F35: =IF(ISNUMBER(E35),E35+ROW()/100000,"") -> 976.00035
A36: ='المركبات النشطة'!C9 -> تنفير حسين | B36: ='المركبات النشطة'!F9 -> ا ر ع 2234 | C36: رخصة السير | D36: ='المركبات النشطة'!N9 -> 46272 | E36: ='المركبات النشطة'!O9 -> 56 | F36: =IF(ISNUMBER(E36),E36+ROW()/100000,"") -> 56.00036
A37: ='المركبات النشطة'!C10 -> محمد مصلح حمادي محسن | B37: ='المركبات النشطة'!F10 -> ا ر و 4140 | C37: رخصة السير | D37: ='المركبات النشطة'!N10 -> 46997 | E37: ='المركبات النشطة'!O10 -> 781 | F37: =IF(ISNUMBER(E37),E37+ROW()/100000,"") -> 781.00037
A38: ='المركبات النشطة'!C11 -> علاء عبد النبي رفاعي احمد | B38: ='المركبات النشطة'!F11 -> ا س 8015 | C38: رخصة السير | D38: ='المركبات النشطة'!N11 -> 46398 | E38: ='المركبات النشطة'!O11 -> 182 | F38: =IF(ISNUMBER(E38),E38+ROW()/100000,"") -> 182.00038
A39: ='المركبات النشطة'!C12 -> رفيق اسان بيلات | B39: ='المركبات النشطة'!F12 -> ا س ق 7776 | C39: رخصة السير | D39: ='المركبات النشطة'!N12 -> 46282 | E39: ='المركبات النشطة'!O12 -> 66 | F39: =IF(ISNUMBER(E39),E39+ROW()/100000,"") -> 66.00039
A40: ='المركبات النشطة'!C13 -> ابراهيم محمد ابوزيد محمد | B40: ='المركبات النشطة'!F13 -> أ ر ع 2233 | C40: رخصة السير | D40: ='المركبات النشطة'!N13 -> 46272 | E40: ='المركبات النشطة'!O13 -> 56 | F40: =IF(ISNUMBER(E40),E40+ROW()/100000,"") -> 56.0004
A41: ='المركبات النشطة'!C14 -> انفير كاريماري عمير | B41: ='المركبات النشطة'!F14 -> ا ر و 4085 | C41: رخصة السير | D41: ='المركبات النشطة'!N14 -> 46858 | E41: ='المركبات النشطة'!O14 -> 642 | F41: =IF(ISNUMBER(E41),E41+ROW()/100000,"") -> 642.00041
A42: ='المركبات النشطة'!C15 -> ارجوان | B42: ='المركبات النشطة'!F15 -> ا س م 8033 | C42: رخصة السير | D42: ='المركبات النشطة'!N15 -> 46398 | E42: ='المركبات النشطة'!O15 -> 182 | F42: =IF(ISNUMBER(E42),E42+ROW()/100000,"") -> 182.00042
A43: ='المركبات النشطة'!C16 -> اجيت راجا | B43: ='المركبات النشطة'!F16 -> ا ر و 4084 | C43: رخصة السير | D43: ='المركبات النشطة'!N16 -> 46858 | E43: ='المركبات النشطة'!O16 -> 642 | F43: =IF(ISNUMBER(E43),E43+ROW()/100000,"") -> 642.00043
... A61: ='المركبات النشطة'!C34 -> محمد عبدالرحمن السيد المندوه | B61: ='المركبات النشطة'!F34 -> أ ص ق 6855 | C61: رخصة السير | D61: ='المركبات النشطة'!N34 -> 46592 | E61: ='المركبات النشطة'!O34 -> 376 | F61: =IF(ISNUMBER(E61),E61+ROW()/100000,"") -> 376.00061
A62: ='المركبات النشطة'!C5 -> شمون مياه ادريس مياه | B62: ='المركبات النشطة'!F5 -> ا س م 8013 | C62: بطاقة السائق | D62: ='المركبات النشطة'!P5 -> 46515 | E62: ='المركبات النشطة'!Q5 -> 299 | F62: =IF(ISNUMBER(E62),E62+ROW()/100000,"") -> 299.00062
A63: ='المركبات النشطة'!C6 -> مارييل فينود | B63: ='المركبات النشطة'!F6 -> أ س م 8025 | C63: بطاقة السائق | D63: ='المركبات النشطة'!P6 -> 46534 | E63: ='المركبات النشطة'!Q6 -> 318 | F63: =IF(ISNUMBER(E63),E63+ROW()/100000,"") -> 318.00063
A64: ='المركبات النشطة'!C7 -> محمد عبدالصبور عبدالعزيز | B64: ='المركبات النشطة'!F7 -> ا س م 8024 | C64: بطاقة السائق | D64: ='المركبات النشطة'!P7 -> 46515 | E64: ='المركبات النشطة'!Q7 -> 299 | F64: =IF(ISNUMBER(E64),E64+ROW()/100000,"") -> 299.00064
A65: ='المركبات النشطة'!C8 -> كابيل مياه | B65: ='المركبات النشطة'!F8 -> ا س ح 8714 | C65: بطاقة السائق | D65: ='المركبات النشطة'!P8 -> 46198 | E65: ='المركبات النشطة'!Q8 -> -18 | F65: =IF(ISNUMBER(E65),E65+ROW()/100000,"") -> -17.99935
A66: ='المركبات النشطة'!C9 -> تنفير حسين | B66: ='المركبات النشطة'!F9 -> ا ر ع 2234 | C66: بطاقة السائق | D66: ='المركبات النشطة'!P9 -> 46515 | E66: ='المركبات النشطة'!Q9 -> 299 | F66: =IF(ISNUMBER(E66),E66+ROW()/100000,"") -> 299.00066
A67: ='المركبات النشطة'!C10 -> محمد مصلح حمادي محسن | B67: ='المركبات النشطة'!F10 -> ا ر و 4140 | C67: بطاقة السائق | D67: ='المركبات النشطة'!P10 -> 46505 | E67: ='المركبات النشطة'!Q10 -> 289 | F67: =IF(ISNUMBER(E67),E67+ROW()/100000,"") -> 289.00067
A68: ='المركبات النشطة'!C11 -> علاء عبد النبي رفاعي احمد | B68: ='المركبات النشطة'!F11 -> ا س 8015 | C68: بطاقة السائق | D68: ='المركبات النشطة'!P11 -> 46515 | E68: ='المركبات النشطة'!Q11 -> 299 | F68: =IF(ISNUMBER(E68),E68+ROW()/100000,"") -> 299.00068
A69: ='المركبات النشطة'!C12 -> رفيق اسان بيلات | B69: ='المركبات النشطة'!F12 -> ا س ق 7776 | C69: بطاقة السائق | D69: ='المركبات النشطة'!P12 -> 46515 | E69: ='المركبات النشطة'!Q12 -> 299 | F69: =IF(ISNUMBER(E69),E69+ROW()/100000,"") -> 299.00069
A70: ='المركبات النشطة'!C13 -> ابراهيم محمد ابوزيد محمد | B70: ='المركبات النشطة'!F13 -> أ ر ع 2233 | C70: بطاقة السائق | D70: ='المركبات النشطة'!P13 -> 46515 | E70: ='المركبات النشطة'!Q13 -> 299 | F70: =IF(ISNUMBER(E70),E70+ROW()/100000,"") -> 299.0007
A71: ='المركبات النشطة'!C14 -> انفير كاريماري عمير | B71: ='المركبات النشطة'!F14 -> ا ر و 4085 | C71: بطاقة السائق | D71: ='المركبات النشطة'!P14 -> 46283 | E71: ='المركبات النشطة'!Q14 -> 67 | F71: =IF(ISNUMBER(E71),E71+ROW()/100000,"") -> 67.00071
A72: ='المركبات النشطة'!C15 -> ارجوان | B72: ='المركبات النشطة'!F15 -> ا س م 8033 | C72: بطاقة السائق | D72: ='المركبات النشطة'!P15 -> 46515 | E72: ='المركبات النشطة'!Q15 -> 299 | F72: =IF(ISNUMBER(E72),E72+ROW()/100000,"") -> 299.00072
A73: ='المركبات النشطة'!C16 -> اجيت راجا | B73: ='المركبات النشطة'!F16 -> ا ر و 4084 | C73: بطاقة السائق | D73: ='المركبات النشطة'!P16 -> 46388 | E73: ='المركبات النشطة'!Q16 -> 172 | F73: =IF(ISNUMBER(E73),E73+ROW()/100000,"") -> 172.00073
... A91: ='المركبات النشطة'!C34 -> محمد عبدالرحمن السيد المندوه | B91: ='المركبات النشطة'!F34 -> أ ص ق 6855 | C91: بطاقة السائق | D91: ='المركبات النشطة'!P34 -> 46543 | E91: ='المركبات النشطة'!Q34 -> 327 | F91: =IF(ISNUMBER(E91),E91+ROW()/100000,"") -> 327.00091
A92: ='المركبات النشطة'!C5 -> شمون مياه ادريس مياه | B92: ='المركبات النشطة'!F5 -> ا س م 8013 | C92: بطاقة التشغيل | D92: ='المركبات النشطة'!R5 -> 46479 | E92: ='المركبات النشطة'!S5 -> 263 | F92: =IF(ISNUMBER(E92),E92+ROW()/100000,"") -> 263.00092
...
